Workbook

Sheet Bến Cát
A1: BIỄU MẪU KIỂM TRA HỆ THỐNG CHIẾU SÁNG TRÊN ĐỊA BÀN PHƯỜNG BẾN CÁT
A3: STT (Theo danh sách Trung tâm) | B3: Tên tủ điều khiển | C3: Tên tủ điều khiển MỚI | D3: Mã QR tủ điều khiển | E3: MÃ PE (Nếu có) | F3: Định vị | G3: Tuyến đường | H3: Phường/Xã | I3: Địa chỉ tủ điều khiển | J3: Lý trình | K3: Chiều dài tuyến | N3: Trạm đèn | S3: Bộ đèn | AD3: Cần đèn | AJ3: Cáp | AL3: Đơn vị khảo sát | AM3: Ngày khảo sát | AN3: Ghi chú | AO3: Đánh giá
K4: Cáp ngầm | L4: Cáp nổi | M4: Tổng cộng | N4: dùng PLC | O4: dùng Timer | P4: Tủ KNTT | Q4: Loại tủ (Thép/ Composite) | R4: Tiếp địa (có hay không) | S4: HPS | W4: LED | X4: Khác (Pha, Trang trí, …) | Y4: Tổng cộng | Z4: Trụ đèn (Trừ các trụ do Điện lực quản lý) | AC4: Tổng cộng | AD4: Đơn | AF4: Đôi Ø60 | AG4: Ba Ø60 | AH4: Bốn Ø60 | AI4: Tổng cộng | AJ4: Cáp từ tủ ra đèn
S5: 100W | T5: 150W | U5: 250W | V5: Khác | Z5: Bê tông | AA5: Kim loại | AB5: TT | AD5: Ø49 | AE5: Ø60 | AJ5: Cáp đồng hay nhôm | AK5: Số sợi (1/2/3/4)
A6: (1) | B6: (2) | D6: (3) | E6: (4) | G6: (5) | H6: (6) | I6: (7) | J6: (8) | K6: (9) | L6: (10) | M6: (11) | N6: (12) | O6: (13) | P6: (14) | Q6: (15) | R6: (16) | S6: (17) | T6: (18) | U6: (19) | V6: (20) | W6: (21) | X6: (22) | Y6: (23) | Z6: (24) | AA6: (25) | AB6: (26) | AC6: (27) | AD6: (28) | AE6: (29) | AF6: (30) | AG6: (31) | AH6: (32) | AI6: (33) | AJ6: (34) | AK6: (35) | AL6: (36) | AM6: (37) | AN6: (38)
B7: =SUBTOTAL(3,B9:B9369) -> 176 | D7: =SUBTOTAL(3,D9:D9369) -> 176 | G7: =SUBTOTAL(3,G9:G9369) -> 176 | H7: =SUBTOTAL(3,H9:H9369) -> 176 | M7: =SUBTOTAL(9,M9:M9369) -> 103157 | S7: =SUBTOTAL(9,S9:S9369) -> 0 | T7: =SUBTOTAL(9,T9:T9369) -> 0 | U7: =SUBTOTAL(9,U9:U9369) -> 665 | V7: =SUBTOTAL(9,V9:V9369) -> 29 | W7: =SUBTOTAL(9,W9:W9369) -> 1632 | X7: =SUBTOTAL(9,X9:X9369) -> 3 | Y7: =SUBTOTAL(9,Y9:Y9369) -> 2329 | Z7: =SUBTOTAL(9,Z9:Z9369) -> 2221 | AA7: =SUBTOTAL(9,AA9:AA9369) -> 74 | AC7: =SUBTOTAL(9,AC9:AC9369) -> 2295 | AD7: =SUBTOTAL(9,AD9:AD9369) -> 68 | AE7: =SUBTOTAL(9,AE9:AE9369) -> 2217 | AF7: =SUBTOTAL(9,AF9:AF9369) -> 14 | AG7: =SUBTOTAL(9,AG9:AG9369) -> 0 | AH7: =SUBTOTAL(9,AH9:AH9369) -> 0 | AI7: =SUBTOTAL(9,AI9:AI9369) -> 2299
A9: 1710 | B9: Trạm CS Lai Hưng 141 | C9: Lai Hưng 141 | D9: 102407000 | E9: No.1611598810 | F9: =VLOOKUP(D9,'[1]Bến Cát'!$E$4:$F$177,2,0) -> 11.179202522906118, 106.63190998342895 | G9: Lai Hưng 141 | H9: Bến Cát | I9: ngay đầu đường Liên Hưng 141 | J9: 01 - 02 | L9: 180 | M9: =SUM(K9:L9) -> 180 | N9: T | O9: F | P9: F | Q9: Thép | R9: Không | W9: 6 | Y9: =SUM(S9:X9) -> 6 | Z9: 6 | AC9: =SUM(Z9:AB9) -> 6 | AE9: 6 | AI9: =SUM(AD9:AH9) -> 6 | AJ9: Nhôm | AK9: 3 | AL9: XN TCME | AM9: 46133 | AO9: Tạm chấp nhận
A10: 1804 | B10: Trạm CS ĐH 604 đường 2/9 Trạm 2 | C10: đường 2/9 ĐH 604-1 | D10: 102729000 | E10: No.25901727 | F10: =VLOOKUP(D10,'[1]Bến Cát'!$E$4:$F$177,2,0) -> 11.1474328, 106.6271701 | G10: đường 2/9 ĐH 604 | H10: Bến Cát | I10: trụ HT 01 lộ 7B | J10: 01 - 03 | L10: 1958 | M10: =SUM(K10:L10) -> 1958 | N10: T | O10: F | P10: F | Q10: Thép | R10: Không | U10: 26 | W10: 3 | Y10: =SUM(S10:X10) -> 29 | Z10: 29 | AC10: =SUM(Z10:AB10) -> 29 | AE10: 29 | AI10: =SUM(AD10:AH10) -> 29 | AJ10: Nhôm | AK10: 3 | AL10: XN TCME | AM10: 46133 | AO10: Đạt
A11: 1708 | B11: Trạm CS Lai Hưng 134 | C11: ĐH 601 | D11: 102052000 | E11: No.21001201 | F11: =VLOOKUP(D11,'[1]Bến Cát'!$E$4:$F$177,2,0) -> 11.183175321419446, 106.62606501263701 | G11: ĐH 601 | H11: Bến Cát | I11: TT 01 ông Khương | J11: 01 - 02 | L11: 400 | M11: =SUM(K11:L11) -> 400 | N11: F | O11: T | P11: F | Q11: Thép | R11: Có | W11: 10 | Y11: =SUM(S11:X11) -> 10 | Z11: 10 | AC11: =SUM(Z11:AB11) -> 10 | AE11: 10 | AI11: =SUM(AD11:AH11) -> 10 | AJ11: Nhôm | AK11: 3 | AL11: XN TCME | AM11: 46133 | AO11: Đạt
A12: 1724 | B12: Trạm CS đường 2/9 - KDC Hưng Phước (cotec) | C12: Giáp đường 2/9 - KDC Hưng Phước | D12: 100885000 | E12: No.241200030669 | F12: =VLOOKUP(D12,'[1]Bến Cát'!$E$4:$F$177,2,0) -> 11.1501617, 106.6190767 | G12: Giáp đường 2/9 - KDC Hưng Phước | H12: Bến Cát | I12: đối diện SN 222/45/2 | J12: 01 - 03 | L12: 284 | M12: =SUM(K12:L12) -> 284 | N12: T | O12: F | P12: F | Q12: Thép | R12: Có | W12: 11 | Y12: =SUM(S12:X12) -> 11 | Z12: 11 | AC12: =SUM(Z12:AB12) -> 11 | AE12: 11 | AI12: =SUM(AD12:AH12) -> 11 | AJ12: Nhôm | AK12: 3 | AL12: XN TCME | AM12: 46133 | AO12: Đạt
A13: 1706 | B13: Trạm CS Lai Hưng 131 | C13: Lai Hưng 131 | D13: 102053000 | E13: No.251200039414 | F13: =VLOOKUP(D13,'[1]Bến Cát'!$E$4:$F$177,2,0) -> 11.179095260067124, 106.62389276244438 | G13: Lai Hưng 131 | H13: Bến Cát | I13: HT-giao giữa đường Lai Hưng 99 và Lai Hưng 131 | J13: 01 - 03 | L13: 840 | M13: =SUM(K13:L13) -> 840 | N13: T | O13: F | P13: F | Q13: Thép | R13: Không | W13: 12 | Y13: =SUM(S13:X13) -> 12 | Z13: 12 | AC13: =SUM(Z13:AB13) -> 12 | AE13: 12 | AI13: =SUM(AD13:AH13) -> 12 | AJ13: Nhôm | AK13: 3 | AL13: XN TCME | AM13: 46133 | AO13: Tạm chấp nhận
A14: 1727 (1728) | B14: Trạm CS MP 119 đường 2/9 | C14: Mỹ Phước 119 | D14: 102731000 | E14: PB.86060 | F14: =VLOOKUP(D14,'[1]Bến Cát'!$E$4:$F$177,2,0) -> 11.1564574, 106.6070764 | G14: Mỹ Phước 119 | H14: Bến Cát | I14: trụ HT 1-5 CS08 | J14: 01 - 04 | L14: 555 | M14: =SUM(K14:L14) -> 555 | N14: F | O14: T | P14: F | Q14: Thép | R14: Có | W14: 19 | Y14: =SUM(S14:X14) -> 19 | Z14: 19 | AC14: =SUM(Z14:AB14) -> 19 | AE14: 19 | AI14: =SUM(AD14:AH14) -> 19 | AJ14: Nhôm | AK14: 2 | AL14: XN TCME | AM14: 46133 | AO14: Đạt
A15: 1750 | B15: Trạm CS giáp đường 2/9 - nhà ông 4 Lướt (MP105) | C15: Mỹ Phước 105 | D15: 100886000 | E15: No.211100268563 | F15: =VLOOKUP(D15,'[1]Bến Cát'!$E$4:$F$177,2,0) -> 11.1531997, 106.6159232 | G15: Mỹ Phước 105 | H15: Bến Cát | I15: SN 113 | J15: 01 - 02 | L15: 320 | M15: =SUM(K15:L15) -> 320 | N15: F | O15: T | P15: F | Q15: Thép | R15: Có | W15: 8 | Y15: =SUM(S15:X15) -> 8 | Z15: 8 | AC15: =SUM(Z15:AB15) -> 8 | AE15: 8 | AI15: =SUM(AD15:AH15) -> 8 | AJ15: Nhôm | AK15: 3 | AL15: XN TCME | AM15: 46133 | AO15: Đạt
A16: 1694 | B16: Trạm CS Lai Hưng 93 Trạm 1 | C16: Lai Hưng 93-1 | D16: 102055000 | E16: No.2211000315336 | F16: =VLOOKUP(D16,'[1]Bến Cát'!$E$4:$F$177,2,0) -> 11.17869460788163, 106.6278175306701 | G16: Lai Hưng 93 | H16: Bến Cát | I16: ngay SN 278 | J16: 01 - 03 | L16: 560 | M16: =SUM(K16:L16) -> 560 | N16: T | O16: F | P16: F | Q16: Thép | R16: Có | W16: 14 | Y16: =SUM(S16:X16) -> 14 | Z16: 14 | AC16: =SUM(Z16:AB16) -> 14 | AE16: 14 | AI16: =SUM(AD16:AH16) -> 14 | AJ16: Nhôm | AK16: 3 | AL16: XN TCME | AM16: 46133 | AO16: Đạt
A17: 1804 (1722) | B17: Trạm CS ĐH 604 đường 2/9 Trạm 1 | C17: đường 2/9 ĐH 604-2 | D17: 102730000 | E17: PB.25901719 | F17: =VLOOKUP(D17,'[1]Bến Cát'!$E$4:$F$177,2,0) -> 11.1532425, 106.6141001 | G17: đường 2/9 ĐH 604 | H17: Bến Cát | I17: trụ HT 01 SN 99 | J17: 01 - 06 | L17: 2220 | M17: =SUM(K17:L17) -> 2220 | N17: T | O17: F | P17: F | Q17: Thép | R17: Có | U17: 27 | W17: 8 | Y17: =SUM(S17:X17) -> 35 | Z17: 35 | AC17: =SUM(Z17:AB17) -> 35 | AE17: 35 | AI17: =SUM(AD17:AH17) -> 35 | AJ17: Nhôm | AK17: 3 | AL17: XN TCME | AM17: 46133 | AO17: Đạt
A18: 1694 | B18: Trạm CS Lai Hưng 93 Trạm 2 | C18: Lai Hưng 93-2 | D18: 102056000 | E18: No.22408046 | F18: =VLOOKUP(D18,'[1]Bến Cát'!$E$4:$F$177,2,0) -> 11.176811580781596, 106.62125025586383 | G18: Lai Hưng 93 | H18: Bến Cát | I18: đối diện TT 12 | J18: 01 - 04 | L18: 1200 | M18: =SUM(K18:L18) -> 1200 | N18: F | O18: T | P18: F | Q18: Thép | R18: Không | W18: 33 | Y18: =SUM(S18:X18) -> 33 | Z18: 33 | AC18: =SUM(Z18:AB18) -> 33 | AE18: 33 | AI18: =SUM(AD18:AH18) -> 33 | AJ18: Nhôm | AK18: 3 | AL18: XN TCME | AM18: 46133 | AO18: Tạm chấp nhận
A19: 1747 | B19: Trạm CS đường 2/9 (Huỳnh Thanh Liêm) Mỹ Phước 91 | C19: Mỹ Phước 91 | D19: 102149000 | E19: No.24100012649 | F19: =VLOOKUP(D19,'[1]Bến Cát'!$E$4:$F$177,2,0) -> 11.147914846961335, 106.62643690629307 | G19: Mỹ Phước 91 | H19: Bến Cát | I19: trụ HT 576 | J19: 01 - 02 | L19: 240 | M19: =SUM(K19:L19) -> 240 | N19: F | O19: T | P19: F | Q19: Thép | R19: Không | W19: 6 | Y19: =SUM(S19:X19) -> 6 | Z19: 6 | AC19: =SUM(Z19:AB19) -> 6 | AE19: 6 | AI19: =SUM(AD19:AH19) -> 6 | AJ19: Nhôm | AK19: 2 | AL19: XN TCME | AM19: 46133 | AO19: Tạm chấp nhận
A20: 1762 | B20: Trạm CS nhà bà Hương Mỹ Phước 95 | C20: Mỹ Phước 95 | D20: 102150000 | E20: No.18110058360 | F20: =VLOOKUP(D20,'[1]Bến Cát'!$E$4:$F$177,2,0) -> 11.149057809097673, 106.62490764179853 | G20: Mỹ Phước 95 | H20: Bến Cát | I20: HT giữ TT 64-65 | J20: 01 - 02 | L20: 200 | M20: =SUM(K20:L20) -> 200 | N20: T | O20: F | P20: F | Q20: Thép | R20: Có | W20: 5 | Y20: =SUM(S20:X20) -> 5 | Z20: 5 | AC20: =SUM(Z20:AB20) -> 5 | AE20: 5 | AI20: =SUM(AD20:AH20) -> 5 | AJ20: Nhôm | AK20: 3 | AL20: XN TCME | AM20: 46133 | AO20: Đạt
A21: 1804 | B21: Trạm CS đồi 2/9 | C21: đường 2/9 ĐH 604-3 | D21: 102732000 | E21: PB.007290 | F21: =VLOOKUP(D21,'[1]Bến Cát'!$E$4:$F$177,2,0) -> 11.1527556, 106.6020705 | G21: đường 2/9 ĐH 604 | H21: Bến Cát | I21: trụ HT 08 SN64 | J21: 01 - 03 | K21: 1360 | M21: =SUM(K21:L21) -> 1360 | N21: T | O21: F | P21: F | Q21: Thép | R21: Không | W21: 64 | Y21: =SUM(S21:X21) -> 64 | AA21: 34 | AC21: =SUM(Z21:AB21) -> 34 | AE21: 21 | AF21: 13 | AI21: =SUM(AD21:AH21) -> 34 | AJ21: Đồng | AK21: 3 | AL21: XN TCME | AM21: 46133 | AO21: Đạt
A22: 1709 | B22: Trạm CS Lai Hưng 137 Trạm 1 | C22: Lai Hưng 137-1 | D22: 102057000 | E22: No.221100336691 | F22: =VLOOKUP(D22,'[1]Bến Cát'!$E$4:$F$177,2,0) -> 11.181500476818995, 106.62970151846514 | G22: Lai Hưng 137 | H22: Bến Cát | I22: TT 14 ông Khương đối diện SN 132 | J22: 01 - 03 | L22: 560 | M22: =SUM(K22:L22) -> 560 | N22: F | O22: T | P22: F | Q22: Thép | R22: Không | W22: 12 | Y22: =SUM(S22:X22) -> 12 | Z22: 12 | AC22: =SUM(Z22:AB22) -> 12 | AE22: 12 | AI22: =SUM(AD22:AH22) -> 12 | AJ22: Nhôm | AK22: 2 | AL22: XN TCME | AM22: 46133 | AO22: Tạm chấp nhận
A23: 1748 | B23: Trạm CS nhà ông Tài Mỹ Phước 101 | C23: Mỹ Phước 101 | D23: 102151000 | E23: No.241200013333 | F23: =VLOOKUP(D23,'[1]Bến Cát'!$E$4:$F$177,2,0) -> 11.151437828690334, 106.62201321164352 | G23: Mỹ Phước 101 | H23: Bến Cát | I23: SN 163/6 | J23: 01 - 03 | L23: 685 | M23: =SUM(K23:L23) -> 685 | N23: F | O23: T | P23: F | Q23: Thép | R23: Có | U23: 17 | Y23: =SUM(S23:X23) -> 17 | Z23: 17 | AC23: =SUM(Z23:AB23) -> 17 | AE23: 17 | AI23: =SUM(AD23:AH23) -> 17 | AJ23: Nhôm | AK23: 3 | AL23: XN TCME | AM23: 46133 | AO23: Đạt
A24: 1720 | B24: Trạm CS Mỹ Phước 92 | C24: Mỹ Phước 92 | D24: 102733000 | E24: No.241200012670 | F24: =VLOOKUP(D24,'[1]Bến Cát'!$E$4:$F$177,2,0) -> 11.1526728, 106.6019373 | G24: Mỹ Phước 92 | H24: Bến Cát | I24: trụ HT 1A1 CS01 | J24: 01 - 02 | L24: 70 | M24: =SUM(K24:L24) -> 70 | N24: F | O24: T | P24: F | Q24: Thép | R24: Có | W24: 3 | Y24: =SUM(S24:X24) -> 3 | Z24: 3 | AC24: =SUM(Z24:AB24) -> 3 | AE24: 3 | AI24: =SUM(AD24:AH24) -> 3 | AJ24: Nhôm | AK24: 2 | AL24: XN TCME | AM24: 46133 | AO24: Đạt
A25: 1709 | B25: Trạm CS Lai Hưng 137 Trạm 2 | C25: Lai Hưng 137-2 | D25: 102058000 | E25: No.221100315825 | F25: =VLOOKUP(D25,'[1]Bến Cát'!$E$4:$F$177,2,0) -> 11.186277845514855, 106.64187243189245 | G25: Lai Hưng 137 | H25: Bến Cát | I25: HT 05H | J25: 01 - 03 | L25: 935 | M25: =SUM(K25:L25) -> 935 | N25: F | O25: T | P25: F | Q25: Thép | R25: Không | W25: 18 | Y25: =SUM(S25:X25) -> 18 | Z25: 18 | AC25: =SUM(Z25:AB25) -> 18 | AE25: 18 | AI25: =SUM(AD25:AH25) -> 18 | AJ25: Nhôm | AK25: 2 | AL25: XN TCME | AM25: 46133 | AO25: Tạm chấp nhận
A26: 1721 | B26: Trạm CS Mỹ Phước 90 | C26: Mỹ Phước 90 | D26: 102734000 | E26: PB.95518 | F26: =VLOOKUP(D26,'[1]Bến Cát'!$E$4:$F$177,2,0) -> 11.1528836, 106.6024231 | G26: Mỹ Phước 90 | H26: Bến Cát | I26: trụ HT 8B SN66 | J26: 01 - 02 | L26: 75 | M26: =SUM(K26:L26) -> 75 | N26: F | O26: T | P26: F | Q26: Thép | R26: Không | W26: 4 | Y26: =SUM(S26:X26) -> 4 | Z26: 4 | AC26: =SUM(Z26:AB26) -> 4 | AE26: 4 | AI26: =SUM(AD26:AH26) -> 4 | AJ26: Nhôm | AK26: 3 | AL26: XN TCME | AM26: 46133 | AO26: Đạt
A27: 1752 | B27: Trạm CS giáp đường 2/9 - nhà ông Cao Văn Nghĩa | C27: Mỹ Phước 113 | D27: 100887000 | E27: PB.92238 | F27: =VLOOKUP(D27,'[1]Bến Cát'!$E$4:$F$177,2,0) -> 11.1556583, 106.610485 | G27: Mỹ Phước 113 | H27: Bến Cát | I27: SN 69/1 | J27: 01 - 05 | L27: 555 | M27: =SUM(K27:L27) -> 555 | N27: F | O27: T | P27: F | Q27: Thép | R27: Có | W27: 17 | Y27: =SUM(S27:X27) -> 17 | Z27: 17 | AC27: =SUM(Z27:AB27) -> 17 | AE27: 17 | AI27: =SUM(AD27:AH27) -> 17 | AJ27: Nhôm | AK27: 2 | AL27: XN TCME | AM27: 46133 | AO27: Đạt
A28: 1709 | B28: Trạm CS Lai Hưng 137 Trạm 3 | C28: Lai Hưng 137-3 | D28: 102059000 | E28: No.221200041156 | F28: =VLOOKUP(D28,'[1]Bến Cát'!$E$4:$F$177,2,0) -> 11.19066872315915, 106.64794286024285 | G28: Lai Hưng 137 | H28: Bến Cát | I28: nằm giữa TT 21 và TT 22 | J28: 01 - 03 | L28: 850 | M28: =SUM(K28:L28) -> 850 | N28: F | O28: T | P28: F | Q28: Thép | R28: Có | W28: 17 | Y28: =SUM(S28:X28) -> 17 | Z28: 17 | AC28: =SUM(Z28:AB28) -> 17 | AE28: 17 | AI28: =SUM(AD28:AH28) -> 17 | AJ28: Nhôm | AK28: 2 | AL28: XN TCME | AM28: 46133 | AO28: Đạt
A29: 1749 | B29: Trạm CS nhà bà Tư sỉ - Út Bửu | C29: Mỹ Phước 103 | D29: 102152000 | E29: No.231200037724 | F29: =VLOOKUP(D29,'[1]Bến Cát'!$E$4:$F$177,2,0) -> 11.153224433791264, 106.61792472033443 | G29: Mỹ Phước 103 | H29: Bến Cát | I29: HT1A4 | J29: 01 - 03 | L29: 400 | M29: =SUM(K29:L29) -> 400 | N29: F | O29: T | P29: F | Q29: Thép | R29: Không | W29: 10 | Y29: =SUM(S29:X29) -> 10 | Z29: 10 | AC29: =SUM(Z29:AB29) -> 10 | AE29: 10 | AI29: =SUM(AD29:AH29) -> 10 | AJ29: Nhôm | AK29: 2 | AL29: XN TCME | AM29: 46133 | AO29: Tạm chấp nhận
A30: 1754 | B30: Trạm CS nhà ông Chu Văn Hùng | C30: Mỹ Phước 123 | D30: 102735000 | E30: No.251200035212 | F30: =VLOOKUP(D30,'[1]Bến Cát'!$E$4:$F$177,2,0) -> 11.1543737, 106.6039045 | G30: Mỹ Phước 123 | H30: Bến Cát | I30: trụ HT 1A4 CS03 | J30: 01 - 03 | L30: 325 | M30: =SUM(K30:L30) -> 325 | N30: T | O30: F | P30: F | Q30: Thép | R30: Có | W30: 10 | Y30: =SUM(S30:X30) -> 10 | Z30: 10 | AC30: =SUM(Z30:AB30) -> 10 | AE30: 10 | AI30: =SUM(AD30:AH30) -> 10 | AJ30: Nhôm | AK30: 3 | AL30: XN TCME | AM30: 46133 | AO30: Đạt
A31: 1711 | B31: Trạm CS Lai Hưng 143 | C31: Lai Hưng 143 | D31: 102060000 | E31: No.221100316103 | F31: =VLOOKUP(D31,'[1]Bến Cát'!$E$4:$F$177,2,0) -> 11.191838198440674, 106.64259462865893 | G31: Lai Hưng 143 | H31: Bến Cát | I31: HT đầu đường Lai Hưng 143 | J31: 01 - 02 | L31: 520 | M31: =SUM(K31:L31) -> 520 | N31: T | O31: F | P31: F | Q31: Thép | R31: Có | W31: 14 | Y31: =SUM(S31:X31) -> 14 | Z31: 14 | AC31: =SUM(Z31:AB31) -> 14 | AE31: 14 | AI31: =SUM(AD31:AH31) -> 14 | AJ31: Nhôm | AK31: 3 | AL31: XN TCME | AM31: 46133 | AO31: Đạt
A32: 1753 | B32: Trạm CS giáp đường 2/9 - nhà bà Giỏi | C32: Mỹ Phước 115 | D32: 100888000 | E32: PB.95519 | F32: =VLOOKUP(D32,'[1]Bến Cát'!$E$4:$F$177,2,0) -> 11.1553594, 106.6086122 | G32: Mỹ Phước 115 | H32: Bến Cát | I32: trụ CS02 | J32: 01 - 05 | L32: 670 | M32: =SUM(K32:L32) -> 670 | N32: T | O32: F | P32: F | Q32: Thép | R32: Có | W32: 15 | Y32: =SUM(S32:X32) -> 15 | Z32: 15 | AC32: =SUM(Z32:AB32) -> 15 | AE32: 15 | AI32: =SUM(AD32:AH32) -> 15 | AJ32: Nhôm | AK32: 3 | AL32: XN TCME | AM32: 46133 | AO32: Đạt
A33: 1707 | B33: Trạm CS Lai Hưng 132 Trạm 1 | C33: Lai Hưng 132-1 | D33: 102061000 | E33: No.251200039417 | F33: =VLOOKUP(D33,'[1]Bến Cát'!$E$4:$F$177,2,0) -> 11.182484457741387, 106.62715112197783 | G33: Lai Hưng 132 | H33: Bến Cát | I33: HT08 | J33: 01 - 02 | L33: 480 | M33: =SUM(K33:L33) -> 480 | N33: T | O33: F | P33: F | Q33: Thép | R33: Có | W33: 9 | Y33: =SUM(S33:X33) -> 9 | Z33: 9 | AC33: =SUM(Z33:AB33) -> 9 | AE33: 9 | AI33: =SUM(AD33:AH33) -> 9 | AJ33: Nhôm | AK33: 3 | AL33: XN TCME | AM33: 46133 | AO33: Đạt
A34: 1751 | B34: Trạm CS nhà đất Thanh Thủy | C34: Mỹ Phước 111 | D34: 102153000 | E34: PB.99681 | F34: =VLOOKUP(D34,'[1]Bến Cát'!$E$4:$F$177,2,0) -> 11.15576358823094, 106.6124875673707 | G34: Mỹ Phước 111 | H34: Bến Cát | I34: HT 1A6 | J34: 01 - 03 | L34: 400 | M34: =SUM(K34:L34) -> 400 | N34: T | O34: F | P34: F | Q34: Thép | R34: Có | W34: 12 | Y34: =SUM(S34:X34) -> 12 | Z34: 12 | AC34: =SUM(Z34:AB34) -> 12 | AE34: 12 | AI34: =SUM(AD34:AH34) -> 12 | AJ34: Nhôm | AK34: 3 | AL34: XN TCME | AM34: 46133 | AO34: Đạt
A35: 1726 | B35: Trạm CS nhà ông Cảnh - Hai Sẳn | C35: Mỹ Phước 109 | D35: 102154000 | E35: No.131138843 | F35: =VLOOKUP(D35,'[1]Bến Cát'!$E$4:$F$177,2,0) -> 11.15425811982715, 106.61412073981683 | G35: Mỹ Phước 109 | H35: Bến Cát | I35: HT 1-4/5 | J35: 01 - 04 | L35: 640 | M35: =SUM(K35:L35) -> 640 | N35: F | O35: T | P35: F | Q35: Thép | R35: Không | W35: 19 | Y35: =SUM(S35:X35) -> 19 | Z35: 19 | AC35: =SUM(Z35:AB35) -> 19 | AE35: 19 | AI35: =SUM(AD35:AH35) -> 19 | AJ35: Nhôm | AK35: 3 | AL35: XN TCME | AM35: 46133 | AO35: Tạm chấp nhận
A36: 1719 (1718) | B36: Trạm CS nhà Lê Thanh Tam Lê Văn Thành | C36: Mỹ Phước 94 | D36: 102736000 | E36: PB.95517 | F36: =VLOOKUP(D36,'[1]Bến Cát'!$E$4:$F$177,2,0) -> 11.1520701, 106.6015212 | G36: Mỹ Phước 94 | H36: Bến Cát | I36: SN 46/9 | J36: 01 - 05 | L36: 455 | M36: =SUM(K36:L36) -> 455 | N36: F | O36: T | P36: F | Q36: Thép | R36: Có | W36: 14 | Y36: =SUM(S36:X36) -> 14 | Z36: 14 | AC36: =SUM(Z36:AB36) -> 14 | AE36: 14 | AI36: =SUM(AD36:AH36) -> 14 | AJ36: Nhôm | AK36: 3 | AL36: XN TCME | AM36: 46133 | AO36: Đạt
A37: 1707 | B37: Trạm CS Lai Hưng 132 Trạm 2 | C37: Lai Hưng 132-2 | D37: 102062000 | E37: No.251200039421 | F37: =VLOOKUP(D37,'[1]Bến Cát'!$E$4:$F$177,2,0) -> 11.18838528387074, 106.63109407297449 | G37: Lai Hưng 132 | H37: Bến Cát | I37: HT giao với đường Lai Hưng 129 | J37: 01 - 02 | L37: 1040 | M37: =SUM(K37:L37) -> 1040 | N37: T | O37: F | P37: F | Q37: Thép | R37: Không | W37: 14 | Y37: =SUM(S37:X37) -> 14 | Z37: 14 | AC37: =SUM(Z37:AB37) -> 14 | AE37: 14 | AI37: =SUM(AD37:AH37) -> 14 | AJ37: Nhôm | AK37: 3 | AL37: XN TCME | AM37: 46133 | AO37: Tạm chấp nhận
A38: 1705 | B38: Trạm CS Lai Hưng 129 | C38: Lai Hưng 129 và Lai Hưng 105 | D38: 102063000 | E38: No.221100365329 | F38: =VLOOKUP(D38,'[1]Bến Cát'!$E$4:$F$177,2,0) -> 11.18673276802226, 106.62830232107365 | G38: Lai Hưng 129 và Lai Hưng 105 | H38: Bến Cát | I38: HT 06B / 22 | J38: 01 - 06 | L38: 1215 | M38: =SUM(K38:L38) -> 1215 | N38: T | O38: F | P38: F | Q38: Thép | R38: Không | W38: 31 | Y38: =SUM(S38:X38) -> 31 | Z38: 31 | AC38: =SUM(Z38:AB38) -> 31 | AE38: 31 | AI38: =SUM(AD38:AH38) -> 31 | AJ38: Nhôm | AK38: 3 | AL38: XN TCME | AM38: 46133 | AO38: Tạm chấp nhận
A39: 1713 | B39: Trạm CS nhà ông Phước Hiệp - Nguyễn Văn Phú | C39: Mỹ Phước 104 | D39: 102155000 | E39: PB.80823 | F39: =VLOOKUP(D39,'[1]Bến Cát'!$E$4:$F$177,2,0) -> 11.150511296525957, 106.59954031848338 | G39: Mỹ Phước 104 | H39: Bến Cát | I39: SN 2/16 | J39: 01 - 04 | L39: 600 | M39: =SUM(K39:L39) -> 600 | N39: F | O39: T | P39: F | Q39: Thép | R39: Có | U39: 1 | W39: 18 | Y39: =SUM(S39:X39) -> 19 | Z39: 18 | AC39: =SUM(Z39:AB39) -> 18 | AE39: 19 | AI39: =SUM(AD39:AH39) -> 19 | AJ39: Nhôm | AK39: 2 | AL39: XN TCME | AM39: 46133 | AO39: Đạt
A40: 1700 | B40: Trạm CS Lai Hưng 119 Trạm 1 | C40: Lai Hưng 119-1 | D40: 102064000 | E40: No.1511290191 | F40: =VLOOKUP(D40,'[1]Bến Cát'!$E$4:$F$177,2,0) -> 11.184791635733395, 106.6239862301753 | G40: Lai Hưng 119 | H40: Bến Cát | I40: đàu đường Lai Hưng 119 | J40: 01 - 02 | L40: 400 | M40: =SUM(K40:L40) -> 400 | N40: T | O40: F | P40: F | Q40: Thép | R40: Có | W40: 11 | Y40: =SUM(S40:X40) -> 11 | Z40: 11 | AC40: =SUM(Z40:AB40) -> 11 | AE40: 11 | AI40: =SUM(AD40:AH40) -> 11 | AJ40: Nhôm | AK40: 3 | AL40: XN TCME | AM40: 46133 | AO40: Đạt
A41: 1702 | B41: Trạm CS Lai Hưng 125 Trạm 1 | C41: Lai Hưng 125-1 | D41: 102065000 | E41: No.1511289244 | F41: =VLOOKUP(D41,'[1]Bến Cát'!$E$4:$F$177,2,0) -> 11.184408873124928, 106.62454690093392 | G41: Lai Hưng 125 | H41: Bến Cát | I41: HT đầu đường Lai Hưng 125 | J41: 01 - 02 | L41: 850 | M41: =SUM(K41:L41) -> 850 | N41: T | O41: F | P41: F | Q41: Thép | R41: Có | W41: 20 | Y41: =SUM(S41:X41) -> 20 | Z41: 20 | AC41: =SUM(Z41:AB41) -> 20 | AE41: 20 | AI41: =SUM(AD41:AH41) -> 20 | AJ41: Nhôm | AK41: 3 | AL41: XN TCME | AM41: 46134 | AO41: Đạt
A42: 1771 | B42: Trạm CS đường QL 13 - ông Nguyễn Văn Thế | C42: Mỹ Phước 23 | D42: 102156000 | E42: PB.1249 | F42: =VLOOKUP(D42,'[1]Bến Cát'!$E$4:$F$177,2,0) -> 11.151814853120626, 106.59871220457713 | G42: Mỹ Phước 23 | H42: Bến Cát | I42: oto Tiến Phát | J42: 01 - 02 | L42: 120 | M42: =SUM(K42:L42) -> 120 | N42: T | O42: F | P42: F | Q42: Thép | R42: Có | W42: 4 | Y42: =SUM(S42:X42) -> 4 | Z42: 4 | AC42: =SUM(Z42:AB42) -> 4 | AE42: 4 | AI42: =SUM(AD42:AH42) -> 4 | AJ42: Nhôm | AK42: 3 | AL42: XN TCME | AM42: 46134 | AO42: Đạt
...

Sheet Bầu Bàng
A1: BIỄU MẪU KIỂM TRA HỆ THỐNG CHIẾU SÁNG TRÊN ĐỊA BÀN XÃ BÀU BÀNG
A3: STT (Theo danh sách Trung tâm) | B3: Tên tủ điều khiển | C3: Mã QR tủ điều khiển | D3: MÃ NO/PE | E3: Định vị | F3: Tuyến đường | G3: Phường/Xã | H3: Địa chỉ tủ điều khiển | I3: Lý trình | J3: Chiều dài tuyến | M3: Trạm đèn | R3: Bộ đèn | AC3: Cần đèn | AI3: Cáp | AK3: Đơn vị khảo sát | AL3: Ngày khảo sát | AM3: Ghi chú | AN3: Đánh giá
J4: Cáp ngầm | K4: Cáp nổi | L4: Tổng cộng | M4: dùng PLC | N4: dùng Timer | O4: Tủ KNTT | P4: Loại tủ (Thép/ Composite) | Q4: Tiếp địa (có hay không) | R4: HPS | V4: LED | W4: Khác (Pha, Trang trí, …) | X4: Tổng cộng | Y4: Trụ đèn (Trừ các trụ do Điện lực quản lý) | AB4: Tổng cộng | AC4: Đơn | AE4: Đôi Ø60 | AF4: Ba Ø60 | AG4: Bốn Ø60 | AH4: Tổng cộng | AI4: Cáp từ tủ ra đèn
R5: 100W | S5: 150W | T5: 250W | U5: Khác | Y5: Bê tông | Z5: Kim loại | AA5: Trang trí | AC5: Ø49 | AD5: Ø60 | AI5: Cáp đồng hay nhôm | AJ5: Số sợi (1/2/3/4)
A6: (1) | B6: (2) | C6: (3) | D6: (4) | F6: (5) | G6: (6) | H6: (7) | I6: (8) | J6: (9) | K6: (10) | L6: (11) | M6: (12) | N6: (13) | O6: (14) | P6: (15) | Q6: (16) | R6: (17) | S6: (18) | T6: (19) | U6: (20) | V6: (21) | W6: (22) | X6: (23) | Y6: (24) | Z6: (25) | AA6: (26) | AB6: (27) | AC6: (28) | AD6: (29) | AE6: (30) | AF6: (31) | AG6: (32) | AH6: (33) | AI6: (34) | AJ6: (35) | AK6: (36) | AL6: (37) | AM6: (38)
B7: =SUBTOTAL(3,B9:B9299) -> 1 | C7: =SUBTOTAL(3,C9:C9299) -> 1 | D7: =SUBTOTAL(3,D9:D9299) -> 1 | F7: =SUBTOTAL(3,F9:F9299) -> 1 | G7: =SUBTOTAL(3,G9:G9299) -> 1 | H7: =SUBTOTAL(3,H9:H9299) -> 0 | I7: =SUBTOTAL(3,I9:I9299) -> 1 | J7: =SUBTOTAL(3,J9:J9299) -> 0 | K7: =SUBTOTAL(3,K9:K9299) -> 1 | L7: =SUBTOTAL(3,L9:L9299) -> 1 | M7: =SUBTOTAL(3,M9:M9299) -> 1 | ... Q7: =SUBTOTAL(3,Q9:Q9299) -> 1 | U7: =SUBTOTAL(3,U9:U9299) -> 0 | V7: =SUBTOTAL(3,V9:V9299) -> 1 | X7: =SUBTOTAL(3,X9:X9299) -> 1 | Y7: =SUBTOTAL(3,Y9:Y9299) -> 1 | Z7: =SUBTOTAL(3,Z9:Z9299) -> 0 | AA7: =SUBTOTAL(3,AA9:AA9299) -> 0 | AB7: =SUBTOTAL(3,AB9:AB9299) -> 1 | AC7: =SUBTOTAL(3,AC9:AC9299) -> 0 | AD7: =SUBTOTAL(3,AD9:AD9299) -> 1 | AE7: =SUBTOTAL(3,AE9:AE9299) -> 0 | ... AM7: =SUBTOTAL(3,AM9:AM9299) -> 0
A9: 2287 | B9: Lai Uyên 19 | C9: 101124000 | D9: No.210045824 | E9: 11.3297471, 106.6333761 | F9: Lai Uyên 19 | G9: Bàu Bàng | H9: 224 | I9: 1-31 | K9: 1473 | L9: =SUM(J9:K9) -> 1473 | M9: F | N9: T | P9: T | Q9: K | U9: 16 | V9: 15 | X9: =SUM(R9:W9) -> 31 | Y9: 31 | AB9: =SUM(Y9:AA9) -> 31 | AC9: 31 | AH9: =SUM(AC9:AG9) -> 31 | AI9: N | AJ9: 3 | AK9: CSKV BẮC | AL9: 46105
A10: 2288 | B10: Lai Uyên 20-2 | C10: 101121000 | D10: No.21004186 | E10: 11.3173873, 106.6321377 | F10: Lai Uyên 20 | G10: Bàu Bàng | H10: 46 TỔ 1 Ấp Bàu Bàng | I10: 1-21 | K10: 752 | L10: =SUM(J10:K10) -> 752 | M10: F | N10: T | P10: T | Q10: K | U10: 21 | X10: =SUM(R10:W10) -> 21 | Y10: 21 | AB10: =SUM(Y10:AA10) -> 21 | AC10: 21 | AH10: =SUM(AC10:AG10) -> 21 | AI10: N | AJ10: 3 | AK10: CSKV BẮC | AL10: 46105
A11: 2288 | B11: Lai Uyên 20-1 | C11: 101120000 | E11: 11.3242289, 106.6305235 | F11: Lai Uyên 20 | G11: Bàu Bàng | H11: gần 115 Lai Uyên 20 | I11: 1-22 | K11: =2103-K13+K14 -> 2028 | L11: =SUM(J11:K11) -> 2028 | M11: F | N11: T | P11: T | Q11: K | U11: 22 | X11: =SUM(R11:W11) -> 22 | Y11: 22 | AB11: =SUM(Y11:AA11) -> 22 | AC11: 22 | AH11: =SUM(AC11:AG11) -> 22 | AI11: N | AJ11: 3 | AK11: CSKV BẮC | AL11: 46105
A12: 2289 | B12: Lai Uyên 22 | C12: 101123000 | D12: No.21080276 | E12: 11.3242245, 106.6320117 | F12: Lai Uyên 22 | G12: Bàu Bàng | H12: 129 | I12: 46143 | K12: 322 | L12: =SUM(J12:K12) -> 322 | M12: F | N12: T | P12: T | Q12: K | U12: 5 | X12: =SUM(R12:W12) -> 5 | Y12: 5 | AB12: =SUM(Y12:AA12) -> 5 | AC12: 5 | AH12: =SUM(AC12:AG12) -> 5 | AI12: N | AJ12: 3 | AK12: CSKV BẮC | AL12: 46105
A13: 2290 | F13: Lai Uyên - 23 | G13: Bàu Bàng | I13: 1-11 | K13: 440 | L13: =SUM(J13:K13) -> 440 | V13: 11 | X13: =SUM(R13:W13) -> 11 | Y13: 11 | AB13: 11 | AC13: 11 | AH13: 11 | AK13: CSKV BẮC
A14: 2291 | F14: Lai Uyên - 24 | G14: Bàu Bàng | I14: 1-10 | K14: 365 | L14: =SUM(J14:K14) -> 365 | V14: 10 | X14: 10 | Y14: 10 | AB14: 10 | AC14: 10 | AH14: 10 | AK14: CSKV BẮC
A15: 2292 | B15: Lai Uyên 25 | C15: 101122000 | D15: No.21072679 | E15: 11.3198451, 106.6325911 | F15: Lai Uyên 25 | G15: Bàu Bàng | H15: đối diện trạm y tế | I15: 46204 | K15: 348 | L15: =SUM(J15:K15) -> 348 | M15: F | N15: T | P15: T | Q15: C | U15: 7 | X15: =SUM(R15:W15) -> 7 | Y15: 7 | AB15: =SUM(Y15:AA15) -> 7 | AC15: 7 | AH15: =SUM(AC15:AG15) -> 7 | AI15: N | AJ15: 3 | AK15: CSKV BẮC | AL15: 46105
A16: 2293 | F16: Lai Uyên - 26 | G16: Bàu Bàng | I16: 1-6 | K16: 345 | U16: 6 | X16: 6 | Y16: 6 | AD16: 6 | AH16: 6 | AK16: CSKV BẮC
A17: 2294 | B17: Lai Uyên 27 | C17: 109314000 | D17: No.21034660 | E17: 11.328234, 106.634969 | F17: Lai Uyên 27 | G17: Bàu Bàng | H17: ngã 3 QL13-Lai Uyên 27 | I17: 1-10 | K17: =555+65 -> 620 | L17: =SUM(J17:K17) -> 620 | N17: T | P17: T | U17: 10 | X17: =SUM(R17:W17) -> 10 | Y17: 10 | AB17: =SUM(Y17:AA17) -> 10 | AD17: 10 | AH17: =SUM(AC17:AG17) -> 10 | AI17: N | AJ17: 3 | AK17: CSKV BẮC | AL17: 46106
A18: 2295 | B18: Lai Uyên 28 | C18: 101313000 | D18: No.21072767 | E18: 11.327118, 106.6347711 | F18: Lai Uyên 28 | G18: Bàu Bàng | H18: Nhà thuốc tây chín Minh Hòa | I18: 1-12 | K18: 710 | L18: =SUM(J18:K18) -> 710 | N18: T | P18: T | U18: 12 | X18: =SUM(R18:W18) -> 12 | Y18: 12 | AB18: =SUM(Y18:AA18) -> 12 | AD18: 12 | AH18: =SUM(AC18:AG18) -> 12 | AI18: N | AJ18: 3 | AK18: CSKV BẮC | AL18: 46106
A19: 2296 | B19: Lai Uyên 29 | C19: 101316000 | D19: No.25092038 | E19: 11.3252714, 106.6361642 | F19: Lai Uyên 29 | G19: Bàu Bàng | I19: 1-8 | K19: 405 | L19: =SUM(J19:K19) -> 405 | N19: T | P19: T | U19: 8 | X19: =SUM(R19:W19) -> 8 | Y19: 8 | AB19: =SUM(Y19:AA19) -> 8 | AD19: 8 | AH19: =SUM(AC19:AG19) -> 8 | AI19: N | AJ19: 3 | AK19: CSKV BẮC | AL19: 46106
A20: 2297 | F20: Lai Uyên 30 | G20: Bàu Bàng | I20: 1-9 | K20: 410 | L20: =SUM(J20:K20) -> 410 | U20: 9 | X20: =SUM(R20:W20) -> 9 | Y20: 9 | AB20: =SUM(Y20:AA20) -> 9 | AD20: 9 | AH20: =SUM(AC20:AG20) -> 9 | AK20: CSKV BẮC | AL20: 46106
A21: 2298 | B21: Lai Uyên 31 | C21: 101151000 | D21: No.1611496202 | E21: 11.3163822, 106.6364142 | F21: Lai Uyên 31 | G21: Bàu Bàng | H21: ĐL2/1 | I21: 1-6 | K21: 195 | L21: =SUM(J21:K21) -> 195 | N21: T | P21: T | V21: 6 | X21: =SUM(R21:W21) -> 6 | AB21: =SUM(Y21:AA21) -> 0 | AD21: 6 | AH21: =SUM(AC21:AG21) -> 6 | AI21: N | AJ21: 3 | AK21: CSKV BẮC | AL21: 46106
A22: 2299 | B22: Lai Uyên 33 | C22: 101153000 | D22: No.21048552 | E22: 11.3188514, 106.6378344 | F22: Lai Uyên 32 | G22: Bàu Bàng | H22: 177 | I22: 1-34 | K22: =245+490+375 -> 1110 | L22: =SUM(J22:K22) -> 1110 | N22: T | P22: T | U22: 9 | V22: 25 | X22: =SUM(R22:W22) -> 34 | Y22: 34 | AB22: =SUM(Y22:AA22) -> 34 | AD22: 34 | AH22: =SUM(AC22:AG22) -> 34 | AI22: N | AJ22: 3 | AK22: CSKV BẮC | AL22: 46106
A23: 2300 | F23: Lai Uyên 33 | G23: Bàu Bàng | I23: 1-3 | K23: 110 | L23: =SUM(J23:K23) -> 110 | U23: 3 | X23: =SUM(R23:W23) -> 3 | Y23: 3 | AB23: =SUM(Y23:AA23) -> 3 | AD23: 3 | AH23: =SUM(AC23:AG23) -> 3 | AK23: CSKV BẮC | AL23: 46106
A24: 2301 | B24: Lai Uyên 33-2 | C24: 101154000 | D24: No.1611166860 | E24: 11.3223577, 106.6404766 | F24: Lai Uyên 34 | G24: Bàu Bàng | H24: ĐL02 | I24: 1-32 | K24: 1495 | L24: =SUM(J24:K24) -> 1495 | N24: T | P24: T | U24: 21 | V24: 11 | X24: =SUM(R24:W24) -> 32 | Y24: 32 | AB24: =SUM(Y24:AA24) -> 32 | AD24: 32 | AH24: =SUM(AC24:AG24) -> 32 | AI24: N | AJ24: 3 | AK24: CSKV BẮC | AL24: 46106
A25: 2302 | B25: Lai Uyên 36 | C25: 101315000 | D25: No.211100282890 | E25: 11.3212317, 106.6431971 | F25: Lai Uyên 36 | G25: Bàu Bàng | I25: 1-19 | K25: =170+560 -> 730 | L25: =SUM(J25:K25) -> 730 | N25: T | P25: T | V25: 19 | X25: =SUM(R25:W25) -> 19 | Y25: 19 | AB25: =SUM(Y25:AA25) -> 19 | AD25: 19 | AH25: =SUM(AC25:AG25) -> 19 | AI25: N | AJ25: 3 | AK25: CSKV BẮC | AL25: 46106
A26: 2303 | B26: Lai Uyên 37 | C26: 101151000 | D26: No.221100335949 | E26: 11.3163822, 106.6364142 | F26: Lai Uyên 37 | G26: Bàu Bàng | H26: ĐL3/3 | I26: 1-20 | K26: =718 -> 718 | L26: =SUM(J26:K26) -> 718 | M26: T | P26: T | V26: 20 | X26: =SUM(R26:W26) -> 20 | Y26: 20 | AB26: =SUM(Y26:AA26) -> 20 | AD26: 20 | AH26: =SUM(AC26:AG26) -> 20 | AI26: N | AJ26: 3 | AK26: CSKV BẮC | AL26: 46106
A27: 2304 | B27: Lai Uyên 39 | C27: 101312000 | E27: 11.3177627, 106.6378529 | F27: Lai Uyên 39 | G27: Bàu Bàng | H27: 159 Ấp Xà Mách | I27: 1-6 | K27: 270 | L27: =SUM(J27:K27) -> 270 | M27: T | P27: T | V27: 6 | X27: =SUM(R27:W27) -> 6 | Y27: 6 | AB27: =SUM(Y27:AA27) -> 6 | AC27: 6 | AH27: =SUM(AC27:AG27) -> 6 | AI27: N | AJ27: 3 | AK27: CSKV BẮC | AL27: 46106
A28: 2305 | F28: Lai Uyên 40 | G28: Bàu Bàng | I28: 1-13 | K28: 511 | L28: =SUM(J28:K28) -> 511 | U28: 13 | X28: =SUM(R28:W28) -> 13 | Y28: 13 | AB28: 13 | AD28: 13 | AH28: 13 | AK28: CSKV BẮC | AL28: 46106
A29: 2306 | B29: Lai Uyên 41 | C29: 101317000 | D29: No.25088053 | E29: 11.3175158, 106.6402463 | F29: Lai Uyên 41 | G29: Bàu Bàng | H29: Ngã 3 ĐH618-Lai uyên 41 | I29: 1-7 | K29: 290 | L29: =SUM(J29:K29) -> 290 | M29: T | P29: T | V29: 7 | X29: =SUM(R29:W29) -> 7 | Y29: 7 | AB29: =SUM(Y29:AA29) -> 7 | AD29: 7 | AH29: =SUM(AC29:AG29) -> 7 | AI29: N | AJ29: 3 | AK29: CSKV BẮC | AL29: 46106
A30: 2307 | B30: Lai Uyên 44 | C30: 101182000 | D30: No.221100308855 | E30: 11.3111464, 106.6269912 | F30: Lai Uyên 44 | G30: Bàu Bàng | I30: 1-19 | K30: 688 | L30: =SUM(J30:K30) -> 688 | N30: T | P30: T | V30: 19 | X30: =SUM(R30:W30) -> 19 | Y30: 19 | AB30: =SUM(Y30:AA30) -> 19 | AD30: 19 | AH30: =SUM(AC30:AG30) -> 19 | AI30: N | AJ30: 3 | AK30: CSKV BẮC | AL30: 46106
A31: 2308 | B31: Lai Uyên 45-1 | C31: 101185000 | D31: No.221100333016 | E31: 11.3034667, 106.6233392 | F31: Lai Uyên 45 | G31: Bàu Bàng | I31: 1-55 | K31: =2007-K33-K34 -> 1428 | L31: =SUM(J31:K31) -> 1428 | M31: T | P31: T | V31: =55-V33-V34 -> 37 | X31: =SUM(R31:W31) -> 37 | Y31: 37 | AB31: =SUM(Y31:AA31) -> 37 | AD31: 37 | AH31: =SUM(AC31:AG31) -> 37 | AI31: N | AJ31: 2 | AK31: CSKV BẮC | AL31: 46106
A32: 2308 | B32: Lai Uyên 45-2 | C32: 101188000 | E32: 11.3034061, 106.606986 | F32: Lai Uyên 45 | G32: Bàu Bàng | I32: 1-25 | K32: 1761 | L32: =SUM(J32:K32) -> 1761 | N32: T | P32: T | V32: 25 | X32: =SUM(R32:W32) -> 25 | Y32: 25 | AB32: =SUM(Y32:AA32) -> 25 | AD32: 25 | AH32: =SUM(AC32:AG32) -> 25 | AI32: N | AJ32: 3 | AK32: CSKV BẮC | AL32: 46106
A33: 2309 | F33: Lai Uyên 46 | G33: Bàu Bàng | I33: =1&"-"&X33 -> 1-4 | K33: 110 | L33: =SUM(J33:K33) -> 110 | V33: 4 | X33: =SUM(R33:W33) -> 4 | Y33: 4 | AB33: 4 | AD33: 4 | AH33: 4 | AK33: CSKV BẮC
A34: 2310 | F34: Lai Uyên 47 | G34: Bàu Bàng | I34: =1&"-"&X34 -> 1-14 | K34: =237+232 -> 469 | L34: =SUM(J34:K34) -> 469 | V34: 14 | X34: =SUM(R34:W34) -> 14 | Y34: 14 | AB34: 14 | AD34: 14 | AH34: 14 | AK34: CSKV BẮC
A35: 2311 | B35: Lai Uyên 51 | C35: 101208000 | E35: 11.2917846, 106.6313945 | F35: Lai Uyên 51 | G35: Bàu Bàng | I35: 1-22 | K35: 860 | L35: =SUM(J35:K35) -> 860 | V35: 22 | X35: =SUM(R35:W35) -> 22 | Y35: 22 | AB35: =SUM(Y35:AA35) -> 22 | AD35: 22 | AH35: =SUM(AC35:AG35) -> 22 | AI35: N | AJ35: 3 | AK35: CSKV BẮC | AL35: 46106
A36: 2312 | B36: Lai Uyên 52-1 | C36: 101170000 | D36: No.21007399 | E36: 11.3106883, 106.6345621 | F36: Lai Uyên 52 | G36: Bàu Bàng | I36: 1-14 | K36: 751 | L36: =SUM(J36:K36) -> 751 | N36: T | P36: T | U36: 7 | X36: =SUM(R36:W36) -> 7 | Y36: 7 | AB36: =SUM(Y36:AA36) -> 7 | AD36: 7 | AH36: =SUM(AC36:AG36) -> 7 | AI36: N | AJ36: 3 | AK36: CSKV BẮC | AL36: 46106
A37: 2312 | B37: Lai Uyên 52-2 | C37: 101173000 | D37: No.21031972 | E37: 11.3126062, 106.6391656 | F37: Lai Uyên 52 | G37: Bàu Bàng | I37: 1-17 | K37: 932 | L37: =SUM(J37:K37) -> 932 | N37: T | P37: T | V37: 17 | X37: =SUM(R37:W37) -> 17 | Y37: 17 | AB37: =SUM(Y37:AA37) -> 17 | AD37: 17 | AH37: =SUM(AC37:AG37) -> 17 | AI37: N | AJ37: 3 | AK37: CSKV BẮC | AL37: 46106
A38: 2312 | B38: Lai Uyên 52-3 | C38: 101176000 | D38: No.22425293 | E38: 11.3059021, 106.6480739 | F38: Lai Uyên 52 | G38: Bàu Bàng | I38: 1-20 | K38: 904 | L38: =SUM(J38:K38) -> 904 | N38: T | P38: T | U38: 7 | V38: 13 | X38: =SUM(R38:W38) -> 20 | Y38: 20 | AB38: =SUM(Y38:AA38) -> 20 | AD38: 20 | AH38: =SUM(AC38:AG38) -> 20 | AI38: N | AJ38: 3 | AK38: CSKV BẮC | AL38: 46106
A39: 2313 | B39: Lai Uyên 53 | C39: 101179000 | D39: No.17115871 | E39: 11.3074862, 106.6501311 | F39: Lai Uyên 53 | G39: Bàu Bàng | I39: 1-6 | K39: 145 | L39: =SUM(J39:K39) -> 145 | M39: T | P39: T | V39: 6 | X39: =SUM(R39:W39) -> 6 | Y39: 6 | AB39: =SUM(Y39:AA39) -> 6 | AD39: 6 | AH39: =SUM(AC39:AG39) -> 6 | AI39: N | AJ39: 3 | AK39: CSKV BẮC | AL39: 46106
A40: 2314 | F40: Lai Uyên 54 | G40: Bàu Bàng | I40: 1-7 | K40: 209 | L40: =SUM(J40:K40) -> 209 | V40: 17 | X40: =SUM(R40:W40) -> 17 | Y40: 17 | AD40: 17 | AH40: 17 | AK40: CSKV BẮC | AL40: 46106
A41: 2315 | B41: Lai Uyên 55-1 | C41: 101246000 | D41: No.89552 | E41: 11.307716, 106.6321799 | F41: Lai Uyên 55 | G41: Bàu Bàng | I41: 46357 | K41: 840 | L41: =SUM(J41:K41) -> 840 | M41: F | N41: T | P41: T | Q41: K | U41: 12 | X41: =SUM(R41:W41) -> 12 | Y41: 12 | AB41: =SUM(Y41:AA41) -> 12 | AC41: 12 | AH41: =SUM(AC41:AG41) -> 12 | AK41: CSKV BẮC | AL41: 46105
A42: 2315 | B42: Lai Uyên 55-2 | C42: 101247000 | D42: No.25288 | E42: 11.3044544, 106.6463031 | F42: Lai Uyên 55 | G42: Bàu Bàng | I42: 46357 | K42: 1025 | L42: =SUM(J42:K42) -> 1025 | M42: F | N42: T | P42: T | Q42: K | U42: 12 | X42: =SUM(R42:W42) -> 12 | Y42: 12 | AB42: =SUM(Y42:AA42) -> 12 | AC42: 12 | AH42: =SUM(AC42:AG42) -> 12 | AI42: Đ | AJ42: 3 | AK42: CSKV BẮC | AL42: 46105
...

Sheet Trừ văn Thố
A1: BIỄU MẪU KIỂM TRA HỆ THỐNG CHIẾU SÁNG TRÊN ĐỊA BÀN XÃ TRỪ VĂN THỐ
A3: STT (Theo danh sách Trung tâm) | B3: Tên tủ điều khiển | C3: Mã QR tủ điều khiển | D3: MÃ NO/PE | E3: Định vị | F3: Tuyến đường | G3: Phường/Xã | H3: Địa chỉ tủ điều khiển | I3: Lý trình | J3: Chiều dài tuyến | M3: Trạm đèn | R3: Bộ đèn | AC3: Cần đèn | AI3: Cáp | AK3: Ghi chú
J4: Cáp ngầm | K4: Cáp nổi | L4: Tổng cộng | M4: dùng PLC | N4: dùng Timer | O4: Tủ KNTT | P4: Loại tủ (Thép/ Composite) | Q4: Tiếp địa (có hay không) | R4: HPS | V4: LED | W4: Khác (Pha, Trang trí, …) | X4: Tổng cộng | Y4: Trụ đèn (Trừ các trụ do Điện lực quản lý) | AB4: Tổng cộng | AC4: Đơn | AE4: Đôi Ø60 | AF4: Ba Ø60 | AG4: Bốn Ø60 | AH4: Tổng cộng | AI4: Cáp từ tủ ra đèn
R5: 100W | S5: 150W | T5: 250W | U5: Khác | Y5: Bê tông | Z5: Kim loại | AA5: TT | AC5: Ø49 | AD5: Ø60 | AI5: Cáp đồng hay nhôm | AJ5: Số sợi (1/2/3/4)
A6: (1) | B6: (2) | C6: (3) | D6: (4) | F6: (5) | G6: (6) | H6: (7) | I6: (8) | J6: (9) | K6: (10) | L6: (11) | M6: (12) | N6: (13) | O6: (14) | P6: (15) | Q6: (16) | R6: (17) | S6: (18) | T6: (19) | U6: (20) | V6: (21) | W6: (22) | X6: (23) | Y6: (24) | Z6: (25) | AA6: (26) | AB6: (27) | AC6: (28) | AD6: (29) | AE6: (30) | AF6: (31) | AG6: (32) | AH6: (33) | AI6: (34) | AJ6: (35) | AK6: (38)
A8: 2226 | B8: Cây trường 03 - T1 | C8: 101738000 | D8: No.1511084750 | E8: 11.3432353, 106.5831461 | F8: Cây trường 03 | G8: Trừ Văn Thố | H8: Ngã ba Cây trường 03 - ĐT750 | I8: ĐT750 <-> số nhà 35 | K8: 240 | L8: =SUM(J8:K8) -> 240 | M8: T | N8: F | O8: F | P8: T | Q8: C | V8: 7 | X8: =R8+S8+T8+U8+V8+W8 -> 7 | Y8: =X8 -> 7 | AB8: =AA8+Z8+Y8 -> 7 | AC8: =X8 -> 7 | AH8: =SUM(AC8:AG8) -> 7 | AI8: N | AJ8: 3
A9: 2227 | B9: Cây trường 05 - T1 | C9: 101739000 | D9: No.211100046934 | E9: 11.3413566, 106.5801553 | F9: Cây trường 05 | G9: Trừ Văn Thố | H9: Đối diện nhà trọ Tư Lợi | I9: ĐT750 <-> cuối đường | K9: 801 | L9: =SUM(J9:K9) -> 801 | M9: F | N9: T | O9: F | P9: T | Q9: C | S9: 13 | X9: =R9+S9+T9+U9+V9+W9 -> 13 | Y9: =X9 -> 13 | AB9: =AA9+Z9+Y9 -> 13 | AC9: =X9 -> 13 | AH9: =SUM(AC9:AG9) -> 13 | AI9: N | AJ9: 3
A10: 2227 | B10: Cây trường 05 - T2 | C10: 101740000 | D10: No.1511033465 | E10: 11.3397621, 106.5711068 | F10: Cây trường 05 | G10: Trừ Văn Thố | H10: Đối diện nhà trọ Hưng Anh | I10: Trụ 4-6 <-> cuối đường | K10: 787 | L10: =SUM(J10:K10) -> 787 | M10: T | N10: F | O10: F | P10: T | Q10: C | S10: 12 | X10: =R10+S10+T10+U10+V10+W10 -> 12 | Y10: =X10 -> 12 | AB10: =AA10+Z10+Y10 -> 12 | AC10: =X10 -> 12 | AH10: =SUM(AC10:AG10) -> 12 | AI10: N | AJ10: 3
A11: 2228 | B11: Cây trường 06 - T1 | C11: 102278000 | D11: No.2011578637 | E11: 11.386981881234, 106.60742936665807 | F11: Cây trường 06 | G11: Trừ Văn Thố | H11: Góc ngã ba ĐT750 - Cây trường 6 | I11: ĐT750 <-> cuối tuyến | K11: 350 | L11: =SUM(J11:K11) -> 350 | M11: T | N11: F | O11: F | P11: T | Q11: K | V11: 9 | X11: =R11+S11+T11+U11+V11+W11 -> 9 | Y11: =X11 -> 9 | AB11: =AA11+Z11+Y11 -> 9 | AC11: =X11 -> 9 | AH11: =SUM(AC11:AG11) -> 9 | AI11: N | AJ11: 3
A12: 2229 | B12: Cây trường 07 - T1 | C12: 102277000 | D12: No.2011577919 | E12: 11.344438861134568, 106.58039194541665 | F12: Cây trường 07 | G12: Trừ Văn Thố | H12: Góc ngã ba ĐT750 - Cây trường 7 | I12: ĐT750 <-> cuối tuyến | K12: 280 | L12: =SUM(J12:K12) -> 280 | M12: T | N12: F | O12: F | P12: T | Q12: K | V12: 8 | X12: =R12+S12+T12+U12+V12+W12 -> 8 | Y12: =X12 -> 8 | AB12: =AA12+Z12+Y12 -> 8 | AC12: =X12 -> 8 | AH12: =SUM(AC12:AG12) -> 8 | AI12: N | AJ12: 3
A13: 2230 | F13: Cây trường 08 | G13: Trừ Văn Thố | K13: 735 | L13: =SUM(J13:K13) -> 735 | V13: 9 | X13: =R13+S13+T13+U13+V13+W13 -> 9 | Y13: =X13 -> 9 | AB13: =AA13+Z13+Y13 -> 9 | AC13: =X13 -> 9 | AH13: =SUM(AC13:AG13) -> 9 | AK13: Chung tủ Cây trường 7
A14: 2231 | B14: Cây trường 09 - T1 | C14: 102276000 | D14: No.221100364813 | E14: 11.341698481711662, 106.57985835346075 | F14: Cây trường 09 | G14: Trừ Văn Thố | H14: Gần TBA 06 Trừ Văn Thố 94 | I14: ĐT750 <-> cuối tuyến | K14: 330 | L14: =SUM(J14:K14) -> 330 | M14: F | N14: T | O14: F | P14: T | Q14: K | V14: 10 | X14: =R14+S14+T14+U14+V14+W14 -> 10 | Y14: =X14 -> 10 | AB14: =AA14+Z14+Y14 -> 10 | AC14: =X14 -> 10 | AH14: =SUM(AC14:AG14) -> 10 | AI14: N | AJ14: 2
A15: 2232 | B15: Cây trường 10 - T1 | C15: 102281000 | D15: No.2320110482 | E15: 11.34481256828747, 106.5794292838374 | F15: Cây trường 10 | G15: Trừ Văn Thố | H15: Cách đường ĐT750 30 trụ thứ 2 | I15: ĐT750 <-> cuối tuyến | K15: 350 | L15: =SUM(J15:K15) -> 350 | M15: F | N15: T | O15: F | P15: T | Q15: K | V15: 9 | X15: =R15+S15+T15+U15+V15+W15 -> 9 | Y15: =X15 -> 9 | AB15: =AA15+Z15+Y15 -> 9 | AC15: =X15 -> 9 | AH15: =SUM(AC15:AG15) -> 9 | AI15: N | AJ15: 2
A16: 2233 | F16: Cây trường 11 | G16: Trừ Văn Thố | K16: 330 | L16: =SUM(J16:K16) -> 330 | S16: 8 | X16: =R16+S16+T16+U16+V16+W16 -> 8 | Y16: =X16 -> 8 | AB16: =AA16+Z16+Y16 -> 8 | AC16: =X16 -> 8 | AH16: =SUM(AC16:AG16) -> 8 | AK16: Chung tủ Đ750 tủ 2
A17: 2234 | B17: Cây trường 12 - T1 | C17: 101731000 | D17: No.2320109001 | E17: 11.3443276, 106.578207 | F17: Cây trường 12 | G17: Trừ Văn Thố | H17: Ngã ba Cây trường 12 - ĐT750 | I17: ĐT750 <-> cuối tuyến | K17: 360 | L17: =SUM(J17:K17) -> 360 | M17: F | N17: T | O17: F | P17: T | Q17: C | S17: 4 | V17: 8 | X17: =R17+S17+T17+U17+V17+W17 -> 12 | Y17: =X17 -> 12 | AB17: =AA17+Z17+Y17 -> 12 | AC17: =X17 -> 12 | AH17: =SUM(AC17:AG17) -> 12 | AI17: N | AJ17: 2
A18: 2235 | B18: Cây trường 13 - T1 | C18: 102280000 | D18: No.1911423559 | E18: 11.341478116201769, 106.57861797247341 | F18: Cây trường 13 | G18: Trừ Văn Thố | H18: Góc ngã ba ĐT750-Cây trường 13 | I18: ĐT750 <-> cuối tuyến | K18: 350 | L18: =SUM(J18:K18) -> 350 | M18: F | N18: T | O18: F | P18: T | Q18: K | V18: 10 | X18: =R18+S18+T18+U18+V18+W18 -> 10 | Y18: =X18 -> 10 | AB18: =AA18+Z18+Y18 -> 10 | AC18: =X18 -> 10 | AH18: =SUM(AC18:AG18) -> 10 | AI18: N | AJ18: 2
A19: 2236 | B19: Cây trường 14 - T1 | C19: 101732000 | D19: No.221100332296 | E19: 11.3463159, 106.5768338 | F19: Cây trường 14 | G19: Trừ Văn Thố | H19: Trước số nhà 153 | I19: ĐT750 <-> trụ 01 | K19: 370 | L19: =SUM(J19:K19) -> 370 | M19: F | N19: T | O19: F | P19: T | Q19: K | V19: 12 | X19: =R19+S19+T19+U19+V19+W19 -> 12 | Y19: =X19 -> 12 | AB19: =AA19+Z19+Y19 -> 12 | AC19: =X19 -> 12 | AH19: =SUM(AC19:AG19) -> 12 | AI19: N | AJ19: 2
A20: 2237 | B20: Cây trường 15 - T1 | C20: 102284000 | D20: No.11577901 | E20: 11.346148601743495, 106.57568299221487 | F20: Cây trường 15 | G20: Trừ Văn Thố | H20: Góc ngã ba ĐT750-Cây trường 15 | I20: ĐT750 <-> cuối tuyến | K20: 500 | L20: =SUM(J20:K20) -> 500 | M20: F | N20: T | O20: F | P20: T | Q20: K | V20: 13 | X20: =R20+S20+T20+U20+V20+W20 -> 13 | Y20: =X20 -> 13 | AB20: =AA20+Z20+Y20 -> 13 | AC20: =X20 -> 13 | AH20: =SUM(AC20:AG20) -> 13 | AI20: N | AJ20: 4
A21: 2238 | B21: Cây trường 16 - T1 | C21: 102279000 | D21: No.2320106186 | E21: 11.341000489687485, 106.57766646858732 | F21: Cây trường 16 | G21: Trừ Văn Thố | H21: Số trụ 1-1A & góc ngã ba ĐT 750- cây trường 16 | I21: ĐT750 <-> cuối tuyến | K21: 230 | L21: =SUM(J21:K21) -> 230 | M21: T | N21: F | O21: F | P21: T | Q21: K | V21: 7 | X21: =R21+S21+T21+U21+V21+W21 -> 7 | Y21: =X21 -> 7 | AB21: =AA21+Z21+Y21 -> 7 | AC21: =X21 -> 7 | AH21: =SUM(AC21:AG21) -> 7 | AI21: N | AJ21: 3
A22: 2239 | F22: Cây trường 17 | G22: Trừ Văn Thố | I22: ĐT750 <-> cuối tuyến | K22: 400 | L22: =SUM(J22:K22) -> 400 | V22: 9 | X22: =R22+S22+T22+U22+V22+W22 -> 9 | Y22: =X22 -> 9 | AB22: =AA22+Z22+Y22 -> 9 | AC22: =X22 -> 9 | AH22: =SUM(AC22:AG22) -> 9 | AK22: Chun tủ Cây trường 18
A23: 2240 | B23: Cây trường 18 - T1 | C23: 102283000 | D23: No.2011581122 | E23: 11.343865371319785, 106.57509827064962 | F23: Cây trường 18 | G23: Trừ Văn Thố | H23: Góc ngã ba ĐT750-Cây trường 18 | I23: ĐT750 <-> cuối tuyến | K23: 350 | L23: =SUM(J23:K23) -> 350 | M23: T | N23: F | O23: F | P23: T | Q23: K | V23: 9 | X23: =R23+S23+T23+U23+V23+W23 -> 9 | Y23: =X23 -> 9 | AB23: =AA23+Z23+Y23 -> 9 | AC23: =X23 -> 9 | AH23: =SUM(AC23:AG23) -> 9 | AI23: N | AJ23: 3
A24: 2241 | B24: Cây trường 19 - T1 | C24: 101756000 | D24: No.2011580660 | E24: 11.3434845, 106.5741063 | F24: Cây trường 19 | G24: Trừ Văn Thố | H24: Trụ 1-4 ngã 3 CT19-ĐT750 | I24: ĐT750 <-> cuối tuyến | K24: 345 | L24: =SUM(J24:K24) -> 345 | M24: F | N24: T | O24: F | P24: T | Q24: C | V24: 10 | X24: =R24+S24+T24+U24+V24+W24 -> 10 | Y24: =X24 -> 10 | AB24: =AA24+Z24+Y24 -> 10 | AC24: =X24 -> 10 | AH24: =SUM(AC24:AG24) -> 10 | AI24: N | AJ24: 3
A25: 2242 | F25: Cây trường 20 | G25: Trừ Văn Thố | I25: ĐT750 <-> cuối tuyến | K25: 391 | L25: =SUM(J25:K25) -> 391 | V25: 11 | X25: =R25+S25+T25+U25+V25+W25 -> 11 | Y25: =X25 -> 11 | AB25: =AA25+Z25+Y25 -> 11 | AC25: =X25 -> 11 | AH25: =SUM(AC25:AG25) -> 11 | AI25: N | AJ25: 3
A26: 2243 | B26: Cây trường 21 - T1 | C26: 101754000 | D26: No.221100332323 | E26: 11.3406307, 106.5734603 | F26: Cây trường 21 | G26: Trừ Văn Thố | H26: Trụ 2-1 CT21 gần TBA06TVT 104 | I26: ĐT750 <-> cuối tuyến | K26: 377 | L26: =SUM(J26:K26) -> 377 | M26: F | N26: T | O26: F | P26: T | Q26: C | V26: 11 | X26: =R26+S26+T26+U26+V26+W26 -> 11 | Y26: =X26 -> 11 | AB26: =AA26+Z26+Y26 -> 11 | AC26: =X26 -> 11 | AH26: =SUM(AC26:AG26) -> 11 | AI26: N | AJ26: 2
A27: 2244 | B27: Cây trường 22 - T1 | C27: 101755000 | D27: No.2320085155 | E27: 11.3435008, 106.5730166 | F27: Cây trường 22 | G27: Trừ Văn Thố | H27: VP ấp Đông THanh CT22 | I27: ĐT750 <-> cuối tuyến | K27: 385 | L27: =SUM(J27:K27) -> 385 | M27: F | N27: T | O27: F | P27: T | Q27: C | V27: 11 | X27: =R27+S27+T27+U27+V27+W27 -> 11 | Y27: =X27 -> 11 | AB27: =AA27+Z27+Y27 -> 11 | AC27: =X27 -> 11 | AH27: =SUM(AC27:AG27) -> 11 | AI27: N | AJ27: 2
A28: 2245 | B28: Cây trường 23 - T1 | C28: 101753000 | D28: No.2011581488 | E28: 11.3430694, 106.5721969 | F28: Cây trường 23 | G28: Trừ Văn Thố | H28: Trước số nhà 55 ngã 3 CT23-ĐT750 | I28: ĐT750 <-> cuối tuyến | K28: 338 | L28: =SUM(J28:K28) -> 338 | M28: T | N28: F | O28: F | P28: T | Q28: K | V28: 9 | X28: =R28+S28+T28+U28+V28+W28 -> 9 | Y28: =X28 -> 9 | AB28: =AA28+Z28+Y28 -> 9 | AC28: =X28 -> 9 | AH28: =SUM(AC28:AG28) -> 9 | AI28: Đ | AJ28: 3
A29: 2246 | F29: Cây trường 24 | G29: Trừ Văn Thố | I29: ĐT750 <-> cuối tuyến | K29: 407 | L29: =SUM(J29:K29) -> 407 | V29: 11 | X29: =R29+S29+T29+U29+V29+W29 -> 11 | Y29: =X29 -> 11 | AB29: =AA29+Z29+Y29 -> 11 | AC29: =X29 -> 11 | AH29: =SUM(AC29:AG29) -> 11 | AI29: Đ | AJ29: 3 | AK29: Chung tủ Cây trường 23
A30: 2247 | B30: Cây trường 25 - T1 | C30: 101751000 | D30: No.2320105427 | E30: 11.3412964, 106.5712611 | F30: Cây trường 25 | G30: Trừ Văn Thố | H30: Trụ 10-B6 | I30: ĐT750 <-> cuối tuyến | K30: 456 | L30: =SUM(J30:K30) -> 456 | M30: T | N30: F | O30: F | P30: T | Q30: C | V30: 12 | X30: =R30+S30+T30+U30+V30+W30 -> 12 | Y30: =X30 -> 12 | AB30: =AA30+Z30+Y30 -> 12 | AC30: =X30 -> 12 | AH30: =SUM(AC30:AG30) -> 12 | AI30: Đ | AJ30: 3
A31: 2248 | B31: Cây trường 26 - T1 | C31: 101752000 | D31: No.2011580669 | E31: 11.3427639, 106.5711067 | F31: Cây trường 26 | G31: Trừ Văn Thố | H31: Ngã 3 CT26-ĐT750 | I31: ĐT750 <-> trụ 107 | K31: 290 | L31: =SUM(J31:K31) -> 290 | M31: F | N31: T | O31: F | P31: T | Q31: K | V31: 5 | X31: =R31+S31+T31+U31+V31+W31 -> 5 | Y31: =X31 -> 5 | AB31: =AA31+Z31+Y31 -> 5 | AC31: =X31 -> 5 | AH31: =SUM(AC31:AG31) -> 5 | AI31: Đ | AJ31: 3
A32: 2249 | B32: Cây trường 27 - T1 | C32: 101749000 | D32: No.221100332305 | E32: 11.3425892, 106.5699054 | F32: Cây trường 27 | G32: Trừ Văn Thố | H32: Trụ 2-8B ngã ba CT27-ĐT750 | I32: ĐT750 <-> cuối tuyến | K32: 480 | L32: =SUM(J32:K32) -> 480 | M32: F | N32: T | O32: F | P32: T | Q32: C | V32: 13 | X32: =R32+S32+T32+U32+V32+W32 -> 13 | Y32: =X32 -> 13 | AB32: =AA32+Z32+Y32 -> 13 | AC32: =X32 -> 13 | AH32: =SUM(AC32:AG32) -> 13 | AI32: N | AJ32: 2
A33: 2250 | B33: Cây trường 28 - T1- | C33: 101750000 | D33: No.221100332309 | E33: 11.3424616, 106.5699234 | F33: Cây trường 28 | G33: Trừ Văn Thố | H33: Ngã 3 CT28-ĐT750 | I33: ĐT750 <-> cuối tuyến | K33: 358 | L33: =SUM(J33:K33) -> 358 | M33: F | N33: T | O33: F | P33: T | Q33: C | V33: 10 | X33: =R33+S33+T33+U33+V33+W33 -> 10 | Y33: =X33 -> 10 | AB33: =AA33+Z33+Y33 -> 10 | AC33: =X33 -> 10 | AH33: =SUM(AC33:AG33) -> 10 | AI33: N | AJ33: 2
A34: 2251 | B34: Cây trường 05 - T2 | C34: 101740000 | F34: Cây trường 29 | G34: Trừ Văn Thố | H34: Đối diện nhà trọ Hưng Anh | I34: ĐT750 <-> Cây trường 05, 29 | K34: 341 | L34: =SUM(J34:K34) -> 341 | M34: T | N34: F | O34: F | P34: T | Q34: C | S34: 5 | X34: =R34+S34+T34+U34+V34+W34 -> 5 | Y34: =X34 -> 5 | AB34: =AA34+Z34+Y34 -> 5 | AC34: =X34 -> 5 | AH34: =SUM(AC34:AG34) -> 5 | AI34: N | AJ34: 3 | AK34: Chung tủ với Công trường 05 - T2
A35: 2252 | B35: Cây trường 30-T1 | C35: 101743000 | D35: No.221100332308 | E35: 11.3430801, 106.5689762 | F35: Cây trường 30 | G35: Trừ Văn Thố | H35: Gần ngã 3 Cây trường 30-ĐT750 | I35: ĐT750 <-> cuối tuyến | K35: =350+39 -> 389 | L35: =SUM(J35:K35) -> 389 | M35: F | N35: T | O35: F | P35: T | Q35: K | V35: 11 | X35: =R35+S35+T35+U35+V35+W35 -> 11 | Y35: =X35 -> 11 | AB35: =AA35+Z35+Y35 -> 11 | AC35: =X35 -> 11 | AH35: =SUM(AC35:AG35) -> 11 | AI35: N | AJ35: 3
A36: 2253 | B36: Cây trường 31-T1 | C36: 101742000 | E36: 11.3422405, 106.5682863 | F36: Cây trường 31 | G36: Trừ Văn Thố | H36: Trụ 11 Ngã 3 cây trường 31-ĐT750 | I36: ĐT750 <-> số nhà 20 | K36: 327 | L36: =SUM(J36:K36) -> 327 | M36: F | N36: T | O36: F | P36: T | Q36: C | V36: 10 | X36: =R36+S36+T36+U36+V36+W36 -> 10 | Y36: =X36 -> 10 | AB36: =AA36+Z36+Y36 -> 10 | AC36: =X36 -> 10 | AH36: =SUM(AC36:AG36) -> 10 | AI36: N | AJ36: 3
A37: 2254 | F37: Cây trường 32 | G37: Trừ Văn Thố | I37: ĐT750 <-> trụ 1-1A | K37: 230 | L37: =SUM(J37:K37) -> 230 | V37: 6 | X37: =R37+S37+T37+U37+V37+W37 -> 6 | Y37: =X37 -> 6 | AB37: =AA37+Z37+Y37 -> 6 | AC37: =X37 -> 6 | AH37: =SUM(AC37:AG37) -> 6 | AI37: N | AJ37: 3 | AK37: Chung tủ với Cây trường 31
A38: 2255 | B38: Cây trường 33-T1 | C38: 102272000 | D38: No.23901594 | E38: 11.34619210382096, 106.56848377558083 | F38: Cây trường 33 | G38: Trừ Văn Thố | H38: Số trụ 05 đèn đường CS D09 Cây trường 33 | I38: ĐT750 <-> Ngã tư trụ số 01 | K38: 1550 | L38: =SUM(J38:K38) -> 1550 | M38: F | N38: T | O38: F | P38: T | Q38: K | S38: 26 | X38: =R38+S38+T38+U38+V38+W38 -> 26 | Y38: =X38 -> 26 | AB38: =AA38+Z38+Y38 -> 26 | AC38: =X38 -> 26 | AH38: =SUM(AC38:AG38) -> 26 | AI38: N | AJ38: 3
A39: 2256 | B39: Cây trường 34-T1 | C39: 101791000 | D39: No.221100338952 | E39: 11.3402417, 106.5632833 | F39: Cây trường 34 | G39: Trừ Văn Thố | H39: Ngã ba Cây trường 34 ĐH750 | I39: ĐH750 <-> cuối tuyến | K39: 250 | L39: =SUM(J39:K39) -> 250 | M39: F | N39: T | O39: F | P39: T | Q39: K | V39: 6 | X39: =R39+S39+T39+U39+V39+W39 -> 6 | Y39: =X39 -> 6 | AB39: =AA39+Z39+Y39 -> 6 | AC39: =X39 -> 6 | AH39: =SUM(AC39:AG39) -> 6 | AI39: N | AJ39: 3
A40: 2257 | B40: Cây trường 35-T1 | C40: 101719000 | D40: No.1511187169 | E40: 11.3393666, 106.5590379 | F40: Cây trường 35 | G40: Trừ Văn Thố | H40: Ngã ba Cây trường 35 ĐH750 | I40: ĐT750 <-> cuối tuyến | K40: 240 | L40: =SUM(J40:K40) -> 240 | M40: F | N40: T | O40: F | P40: T | Q40: C | V40: 8 | X40: =R40+S40+T40+U40+V40+W40 -> 8 | Y40: =X40 -> 8 | AB40: =AA40+Z40+Y40 -> 8 | AC40: =X40 -> 8 | AH40: =SUM(AC40:AG40) -> 8 | AI40: N | AJ40: 3
A41: 2258 | B41: Cây trường 36-T1 | C41: 101717000 | E41: 11.3392406, 106.5573931 | F41: Cây trường 36 | G41: Trừ Văn Thố | H41: Ngã ba Cây trường 36 ĐH750 | I41: ĐT750 <-> cuối tuyến | K41: 490 | L41: =SUM(J41:K41) -> 490 | M41: F | N41: T | O41: F | P41: T | Q41: C | V41: 9 | X41: =R41+S41+T41+U41+V41+W41 -> 9 | Y41: =X41 -> 9 | AB41: =AA41+Z41+Y41 -> 9 | AC41: =X41 -> 9 | AH41: =SUM(AC41:AG41) -> 9 | AI41: N | AJ41: 3
A42: 2259 | B42: Cây trường 37-T1 | C42: 101744000 | D42: No.1511230035 | E42: 11.3382603, 106.5550423 | F42: Cây trường 37 | G42: Trừ Văn Thố | K42: 298 | L42: =SUM(J42:K42) -> 298 | M42: F | N42: T | O42: F | P42: T | Q42: C | V42: 6 | X42: =R42+S42+T42+U42+V42+W42 -> 6 | Y42: =X42 -> 6 | AB42: =AA42+Z42+Y42 -> 6 | AC42: =X42 -> 6 | AH42: =SUM(AC42:AG42) -> 6 | AI42: N | AJ42: 3
...

Sheet Tổng
A1: PHÂN CẤP SƠ BỘ
A3: STT (Theo danh sách Trung tâm) | B3: Tên tủ điều khiển | C3: Mã QR tủ điều khiển | D3: MÃ NO | E3: MÃ PE / NO kiểm tra lại | G3: MÃ PE | H3: Định vị TĐK | K3: Tuyến đường | L3: Phường/Xã | M3: Địa chỉ tủ điều khiển | N3: Lý trình | O3: Chiều dài tuyến | R3: Trạm đèn | W3: Bộ đèn | AH3: Cần đèn | AN3: Cáp | AP3: Ghi chú
O4: Cáp ngầm | P4: Cáp nổi | Q4: Tổng cộng | R4: dùng PLC | S4: dùng Timer | T4: Tủ KNTT | U4: Loại tủ (Thép/ Composite) | V4: Tiếp địa (có hay không) | W4: HPS | AA4: LED | AB4: Khác (Pha, Trang trí, …) | AC4: Tổng cộng | AD4: Trụ đèn (Trừ các trụ do Điện lực quản lý) | AG4: Tổng cộng | AH4: Đơn | AJ4: Đôi Ø60 | AK4: Ba Ø60 | AL4: Bốn Ø60 | AM4: Tổng cộng | AN4: Cáp từ tủ ra đèn
W5: 100W | X5: 150W | Y5: 250W | Z5: Khác | AD5: Bê tông | AE5: Kim loại | AF5: TT | AH5: Ø49 | AI5: Ø60 | AN5: Cáp đồng hay nhôm | AO5: Số sợi (1/2/3/4)
A6: (1) | B6: (2) | C6: (3) | D6: (4) | K6: (5) | L6: (6) | M6: (7) | N6: (8) | O6: (9) | P6: (10) | Q6: (11) | R6: (12) | S6: (13) | T6: (14) | U6: (15) | V6: (16) | W6: (17) | X6: (18) | Y6: (19) | Z6: (20) | AA6: (21) | AB6: (22) | AC6: (23) | AD6: (24) | AE6: (25) | AF6: (26) | AG6: (27) | AH6: (28) | AI6: (29) | AJ6: (30) | AK6: (31) | AL6: (32) | AM6: (33) | AN6: (34) | AO6: (35) | AP6: (36)
B7: =SUBTOTAL(3,B9:B9368) -> 340 | C7: =SUBTOTAL(3,C9:C9368) -> 334 | D7: =SUBTOTAL(3,D9:D9368) -> 325 | F7: =SUBTOTAL(3,F9:F9368) -> 320 | G7: =SUBTOTAL(3,G9:G9368) -> 249 | H7: =SUBTOTAL(3,H9:H9368) -> 334 | K7: =SUBTOTAL(3,K9:K9368) -> 372 | L7: =SUBTOTAL(3,L9:L9368) -> 372 | M7: =SUBTOTAL(3,M9:M9368) -> 288 | Q7: =SUBTOTAL(9,Q9:Q9368) -> 244586 | W7: =SUBTOTAL(9,W9:W9368) -> 0 | X7: =SUBTOTAL(9,X9:X9368) -> 269 | Y7: =SUBTOTAL(9,Y9:Y9368) -> 659 | Z7: =SUBTOTAL(9,Z9:Z9368) -> 510 | AA7: =SUBTOTAL(9,AA9:AA9368) -> 4352 | AB7: =SUBTOTAL(9,AB9:AB9368) -> 24 | AC7: =SUBTOTAL(9,AC9:AC9368) -> 5814 | AD7: =SUBTOTAL(9,AD9:AD9368) -> 5018 | AE7: =SUBTOTAL(9,AE9:AE9368) -> 430 | AG7: =SUBTOTAL(9,AG9:AG9368) -> 5425 | AH7: =SUBTOTAL(9,AH9:AH9368) -> 1729 | AI7: =SUBTOTAL(9,AI9:AI9368) -> 3378 | AJ7: =SUBTOTAL(9,AJ9:AJ9368) -> 334 | AK7: =SUBTOTAL(9,AK9:AK9368) -> 11 | AL7: =SUBTOTAL(9,AL9:AL9368) -> 0 | AM7: =SUBTOTAL(9,AM9:AM9368) -> 5420
A9: 1638 | B9: Trạm CS ĐT 741B | C9: 101288000 | D9: 21001204 | F9: =VLOOKUP(D9,'rà soát ĐK'!B2:C452,2,0) -> PB04090010364 | G9: PB04090010364 | H9: 11.2654794, 106.644207 | I9: 112654794 | J9: 106644207 | K9: ĐT 741B | L9: Bến Cát | M9: TBA 1x15KVA 18 | N9: 01 - 03 | P9: 2400 | Q9: =SUM(O9:P9) -> 2400 | R9: F | S9: T | T9: F | U9: Thép | V9: Có | Y9: 34 | AC9: =SUM(W9:AB9) -> 34 | AD9: 34 | AG9: =SUM(AD9:AF9) -> 34 | AI9: 34 | AM9: =SUM(AH9:AL9) -> 34 | AN9: Nhôm | AO9: 3
A10: 1638 | B10: Trạm Cs ĐT 741B Trạm 1 | C10: 102701000 | D10: 2321001439 | F10: =VLOOKUP(D10,'rà soát ĐK'!B3:C453,2,0) -> PB04090007937 | G10: PB04090007937 | H10: 11.2524295, 106.6608964 | I10: 112524295 | J10: 1066608964 | K10: ĐT 741B | L10: Bến Cát | M10: TBA 1x15KVA 49 | N10: 01 - 04 | P10: 2680 | Q10: =SUM(P10) -> 2680 | R10: T | S10: F | T10: F | U10: Thép | V10: Không | Y10: 33 | AC10: =SUM(W10:AB10) -> 33 | AD10: 33 | AG10: =SUM(AD10:AF10) -> 33 | AI10: 33 | AM10: =SUM(AH10:AL10) -> 33 | AN10: Nhôm | AO10: 3
A11: 1638 | B11: Trạm CS ĐT 741B Trạm 2 | C11: 102118000 | D11: 2321001464 | F11: =VLOOKUP(D11,'rà soát ĐK'!B4:C454,2,0) -> PB04090010363 | G11: PB04090010363 | H11: 11.2401682, 106.6753898 | I11: 112401682 | J11: 1066753898 | K11: ĐT 741B | L11: Bến Cát | M11: TBA 1x15KVA 77 | N11: 01 - 03 | P11: 1300 | Q11: =SUM(O11:P11) -> 1300 | R11: F | S11: T | T11: F | U11: Thép | V11: Không | Y11: 18 | AC11: =SUM(W11:AB11) -> 18 | AD11: 18 | AG11: =SUM(AD11:AF11) -> 18 | AI11: 18 | AM11: =SUM(AH11:AL11) -> 18 | AN11: Nhôm | AO11: 3
A12: 1645 | B12: Trạm CS Tân Hưng 27 | C12: 103001000 | D12: 21039952 | F12: =VLOOKUP(D12,'rà soát ĐK'!B5:C455,2,0) -> PB04090034471 | G12: PB04090034471 | H12: 11.2564605, 106.6638722 | I12: 112564605 | J12: 1066638722 | K12: Tân Hưng 27 | L12: Bến Cát | M12: THT 1/3 | N12: 01 - 02 | P12: 450 | Q12: =SUM(O12:P12) -> 450 | R12: F | S12: T | T12: F | U12: Thép | V12: Không | AA12: 9 | AC12: =SUM(W12:AB12) -> 9 | AD12: 9 | AG12: =SUM(AD12:AF12) -> 9 | AI12: 9 | AM12: =SUM(AH12:AL12) -> 9 | AN12: Nhôm | AO12: 3
A13: 1654 | B13: Trạm CS Tân Hưng 61 Trạm 1 | C13: 101276000 | D13: 1511178832 | F13: =VLOOKUP(D13,'rà soát ĐK'!B6:C456,2,0) -> PB04090032511 | G13: PB04090032511 | H13: 11.2722213, 106.6405633 | I13: 112722213 | J13: 1066405633 | K13: Tân Hưng 61 | L13: Bến Cát | M13: HT 1/3 | N13: 01 - 03 | P13: 780 | Q13: =SUM(O13:P13) -> 780 | R13: T | S13: F | T13: F | U13: Thép | V13: Có | AA13: 13 | AC13: =SUM(W13:AB13) -> 13 | AD13: 13 | AG13: =SUM(AD13:AF13) -> 13 | AI13: 13 | AM13: =SUM(AH13:AL13) -> 13 | AN13: Nhôm | AO13: 3
A14: 1654 | B14: Trạm CS Tân Hưng 61 Trạm 2 | C14: 101274000 | D14: 1511187168 | F14: =VLOOKUP(D14,'rà soát ĐK'!B7:C457,2,0) -> PB04090032512 | G14: PB04090032512 | H14: 11.2793777, 106.6421409 | I14: 112793777 | J14: 1066421409 | K14: Tân Hưng 61 | L14: Bến Cát | M14: Trụ TT B TAH4/09 T017T | N14: 01 - 03 | P14: 1080 | Q14: =SUM(O14:P14) -> 1080 | R14: T | S14: F | T14: F | U14: Thép | V14: Có | AA14: 18 | AC14: =SUM(W14:AB14) -> 18 | AD14: 18 | AG14: =SUM(AD14:AF14) -> 18 | AI14: 18 | AM14: =SUM(AH14:AL14) -> 18 | AN14: Nhôm | AO14: 3
A15: 1655 | B15: Trạm CS Lai Hưng 63 Trạm 3 | C15: 102704000 | D15: 1611025980 | F15: =VLOOKUP(D15,'rà soát ĐK'!B8:C458,2,0) -> PB04090023096 | G15: PB04090023096 | H15: 11.2557884, 106.6578488 | I15: 112557884 | J15: 1066578488 | K15: Tân Hưng 63 | L15: Bến Cát | M15: THT 4/2 | N15: 01 - 07 | P15: 600 | Q15: =SUM(O15:P15) -> 600 | R15: F | S15: T | T15: F | U15: Thép | V15: Không | Y15: 8 | Z15: 3 | AC15: =SUM(W15:AB15) -> 11 | AD15: 11 | AG15: =SUM(AD15:AF15) -> 11 | AH15: 3 | AI15: 8 | AM15: =SUM(AH15:AL15) -> 11 | AN15: Nhôm | AO15: 3
A16: 1655 | B16: Trạm CS Tân Hưng 63 Trạm 6 | C16: 102707000 | D16: 21072303 | F16: =VLOOKUP(D16,'rà soát ĐK'!B9:C459,2,0) -> PB04090023099 | G16: PB04090023099 | H16: ` | I16: 112442979 | J16: 106671892 | K16: Tân Hưng 63 | L16: Bến Cát | M16: THT 4/1 | N16: 01 - 08 | P16: 540 | Q16: =SUM(O16:P16) -> 540 | R16: F | S16: T | T16: F | U16: Thép | V16: Không | Y16: 6 | Z16: 4 | AC16: =SUM(W16:AB16) -> 10 | AD16: 10 | AG16: =SUM(AD16:AF16) -> 10 | AH16: 4 | AI16: 6 | AM16: =SUM(AH16:AL16) -> 10 | AN16: Nhôm | AO16: 2
A17: 1656 | B17: Trạm CS đường Bìa Lô 2, 3, 4 Trạm 1 | C17: 101279000 | D17: PB.04040069605 | F17: PB.04040069605 | G17: PB.04040069605 | H17: 11.2695966, 106.6415934 | I17: 112695966 | J17: 1066415934 | K17: đường bìa lô 2, 3, 4 | L17: Bến Cát | M17: trụ HT 31 - 1 - 13 | N17: 01 - 03 | P17: 340 | Q17: =SUM(O17:P17) -> 340 | R17: T | S17: F | T17: F | U17: Thép | V17: Có | AA17: 7 | AC17: =SUM(W17:AB17) -> 7 | AD17: 7 | AG17: =SUM(AD17:AF17) -> 7 | AI17: 7 | AM17: =SUM(AH17:AL17) -> 7 | AN17: Nhôm | AO17: 3
A18: 1656 | B18: Trạm CS đường Bìa Lô 2, 3, 4 Trạm 2 | C18: 101280000 | D18: 1511187163 | F18: =VLOOKUP(D18,'rà soát ĐK'!B11:C461,2,0) -> PB04090032505 | G18: PB04090032505 | H18: =VLOOKUP(C18,'[1]Bến Cát'!$E$4:$F$177,2,0) -> 11.2673819, 106.6458982 | I18: 112673819 | J18: 1066458982 | K18: đường bìa lô 2, 3, 4 | L18: Bến Cát | M18: trụ HT 4H-12 | N18: 01 - 03 | P18: 400 | Q18: =SUM(O18:P18) -> 400 | R18: T | S18: F | T18: F | U18: Thép | V18: Có | AA18: 7 | AC18: =SUM(W18:AB18) -> 7 | AD18: 7 | AG18: =SUM(AD18:AF18) -> 7 | AI18: 7 | AM18: =SUM(AH18:AL18) -> 7 | AN18: Nhôm | AO18: 3
A19: 1656 | B19: Trạm CS đường Bìa Lô 2, 3, 4 Trạm 3 | C19: 101282000 | D19: 2011582307 | F19: =VLOOKUP(D19,'rà soát ĐK'!B12:C462,2,0) -> #N/A | H19: =VLOOKUP(C19,'[1]Bến Cát'!$E$4:$F$177,2,0) -> 11.26113, 106.6525983 | I19: 1126113 | J19: 1066525983 | K19: đường bìa lô 2, 3, 4 | L19: Bến Cát | M19: HT 44-4 | N19: 01 - 03 | P19: 540 | Q19: =SUM(O19:P19) -> 540 | R19: T | S19: F | T19: F | U19: Thép | V19: Có | AA19: 9 | AC19: =SUM(W19:AB19) -> 9 | AD19: 9 | AG19: =SUM(AD19:AF19) -> 9 | AI19: 9 | AM19: =SUM(AH19:AL19) -> 9 | AN19: Nhôm | AO19: 3
A20: 1656 | B20: Trạm CS đường Bìa Lô 2, 3, 4 Trạm 4 | C20: 101283000 | D20: PB.04010011349 | F20: PB.04010011349 | G20: PB.04010011349 | H20: =VLOOKUP(C20,'[1]Bến Cát'!$E$4:$F$177,2,0) -> 11.2572522, 106.6571405 | I20: 112572522 | J20: 1066571405 | K20: đường bìa lô 2, 3, 4 | L20: Bến Cát | M20: HT 03-2-7 | N20: 01- 03 | P20: 480 | Q20: =SUM(O20:P20) -> 480 | R20: T | S20: F | T20: F | U20: Thép | V20: Có | AA20: 9 | AC20: =SUM(W20:AB20) -> 9 | AD20: 9 | AG20: =SUM(AD20:AF20) -> 9 | AI20: 9 | AM20: =SUM(AH20:AL20) -> 9 | AN20: Nhôm | AO20: 3
A21: 1656 | B21: Trạm CS đường Bìa Lô 2, 3, 4 Trạm 5 | C21: 101285000 | D21: PB.04010032508 | F21: PB.04010032508 | G21: PB.04010032508 | H21: =VLOOKUP(C21,'[1]Bến Cát'!$E$4:$F$177,2,0) -> 11.2549962, 106.6611164 | I21: 112549962 | J21: 1066611164 | K21: đường bìa lô 2, 3, 4 | L21: Bến Cát | M21: HT 3-6-10 | N21: 01 - 03 | P21: 130 | Q21: =SUM(O21:P21) -> 130 | R21: F | S21: T | T21: F | U21: Thép | V21: Có | AA21: 3 | AC21: =SUM(W21:AB21) -> 3 | AD21: 3 | AG21: =SUM(AD21:AF21) -> 3 | AI21: 3 | AM21: =SUM(AH21:AL21) -> 3 | AN21: Nhôm | AO21: 3
A22: 1656 | B22: Trạm CS đường Bìa Lô 2, 3, 4 Trạm 6 | C22: 101286000 | D22: 151187154 | F22: =VLOOKUP(D22,'rà soát ĐK'!B15:C465,2,0) -> #N/A | H22: =VLOOKUP(C22,'[1]Bến Cát'!$E$4:$F$177,2,0) -> 11.252712, 106.6629862 | I22: 11252712 | J22: 1066629862 | K22: đường bìa lô 2, 3, 4 | L22: Bến Cát | M22: gần tiệm rửa xe Tư Đăng | N22: 01 - 03 | P22: 420 | Q22: =SUM(O22:P22) -> 420 | R22: T | S22: F | T22: F | U22: Thép | V22: Có | AA22: 7 | AC22: =SUM(W22:AB22) -> 7 | AD22: 7 | AG22: =SUM(AD22:AF22) -> 7 | AI22: 7 | AM22: =SUM(AH22:AL22) -> 7 | AN22: Nhôm | AO22: 3
